Workbook
Name _SCM01: #REF!
Name _SCM01: #REF!
Name _SCM02: #REF!
Name _SCM02: #REF!
Name ACCR1: #REF!
Name ACCR1: #REF!
Name accruals: #REF!
Name accruals: #REF!
Name adi_ars: #REF!
Name adi_ars: #REF!
Name ADI_less1m: #REF!
Name ADI_less1m: #REF!
Name adi_total_type: #REF!
Name adi_total_type: #REF!
Name adi_type_less1m: #REF!
Name adi_type_less1m: #REF!
Name adj: #REF!
Name adj: #REF!
Name AK: #REF!
Name AK: #REF!
Name AMMORT: #REF!:#REF!
Name AMMORT: #REF!:#REF!
Name Ammortamenti: #REF!:#REF!
Name Ammortamenti: #REF!:#REF!
Name Anag: #REF!
Name Anag: #REF!
Name anagr: #REF!
Name anagr: #REF!
Name ANAGRAFICA: #REF!
Name ANAGRAFICA: #REF!
Name answer: FALSE
Name ARS: #REF!
Name ARS: #REF!
Name ars_change: #REF!
Name ars_change: #REF!
Name AT: #REF!
Name AT: #REF!
Name AT15JAN: #REF!
Name AT15JAN: #REF!
Name ATAPR15: #REF!
Name ATAPR15: #REF!
Name ATAUG14: #REF!
Name ATAUG14: #REF!
Name ATAUG15: #REF!
Name ATAUG15: #REF!
Name ATDEC: #REF!
Name ATDEC: #REF!
Name ATDEC15: #REF!
Name ATDEC15: #REF!
Name ATDEC2: #REF!
Name ATDEC2: #REF!
Name ATDEC3: #REF!
Name ATDEC3: #REF!
Name ATDEC4: #REF!
Name ATDEC4: #REF!
Name ATFEB: #REF!
Name ATFEB: #REF!
Name ATFEB16: #REF!
Name ATFEB16: #REF!
Name ATfeb16corr: #REF!

Sheet Note
A1: Terms & Acronym:
A2: YTD | B2: Year to date refers to the period of time beginning the first day of the current calendar year up to the current date
A3: LY or PYTD | B3: Last year refers to the sameperiod of last year
A4: PY or FY'23 | B4: Sum of 12 month for the previous/past year or Full Year 2023
A5: Rolling L12M | B5: Previous year means Last 12 months of the reporting period
A6: YoY % Growth | B6: Rate of change used to compare the performance of a business over tow consecutive years

Sheet Delivery
A1: Customer Experience & Responsiveness
A2: On Time In Full (OTIF) (in %)
A3: (Orders delivered on time and in full​ / Total orders delivered) × 100
A4: BU | C4: 45688 | D4: 45716 | E4: 45747 | F4: 45777 | G4: 45808 | H4: 45838 | I4: 45869 | J4: 45900 | K4: 45930 | L4: 45961 | M4: 45991 | N4: 46022 | O4: 46053 | P4: 46081 | Q4: 46112 | R4: 46142 | S4: 46173 | T4: 46203 | U4: YTD | V4: TARGET | W4: +/- Vs trgt | X4: MoM% | Y4: FY'25 | Z4: % Var. Vs FY'25
A5: Safety | B5: OTIF 1st conf | C5: 0.5 | D5: 0.4 | E5: 0.7 | F5: 0 | G5: 0.33 | H5: 0.375 | I5: 1 | J5: 1 | K5: 0.57 | L5: 1 | M5: 1 | N5: 1 | O5: 0.5 | P5: 0.63 | Q5: 0.86 | R5: 0.36 | S5: 0.89 | T5: 0.2 | U5: 0.58333333 | V5: 0.83 | W5: =+U5-V5 -> -0.24666667 | X5: =IFERROR(T5/S5-1,100%) -> -0.7752809 | Y5: 0.73 | Z5: =+U5/Y5-1 -> -0.20091324
B6: MO count | C6: 6 | D6: 5 | E6: 10 | F6: 1 | G6: 9 | H6: 8 | I6: 19 | J6: 3 | K6: 7 | L6: 9 | M6: 14 | N6: 3 | O6: 8 | P6: 8 | Q6: 7 | R6: 11 | S6: 9 | T6: 5 | U6: =SUM(O6:T6) -> 48 | Y6: 94
A7: Leather | B7: OTIF 1st conf | C7: 0.11 | D7: 0.43 | E7: 0.92 | F7: 0 | G7: 0.46 | H7: 0.2 | I7: 0.78 | K7: 0.5 | L7: 1 | M7: 1 | N7: 1 | O7: 0.88 | P7: 0.38 | Q7: 1 | R7: 0 | S7: 0.25 | T7: 0.42857143 | U7: 0.55102041 | V7: 0.69 | W7: =+U7-V7 -> -0.13897959 | X7: =IFERROR(T7/S7-1,100%) -> 0.71428571 | Y7: 0.59 | Z7: =+U7/Y7-1 -> -0.066067105
B8: MO count | C8: 18 | D8: 7 | E8: 13 | F8: 4 | G8: 13 | H8: 5 | I8: 9 | J8: 0 | K8: 6 | L8: 9 | M8: 22 | N8: 3 | O8: 8 | P8: 8 | Q8: 10 | R8: 5 | S8: 4 | T8: 14 | U8: =SUM(O8:T8) -> 49 | Y8: 109
A9: D|air | B9: OTIF 1st conf | C9: 0.5 | D9: 0.78 | E9: 1 | F9: 0 | G9: 1 | H9: 1 | I9: 0.75 | J9: 1 | K9: 0.6 | L9: 1 | M9: 1 | N9: 1 | O9: 1 | P9: 1 | Q9: 1 | R9: 0.5 | S9: 1 | T9: 0.85714286 | U9: 0.89473684 | V9: 0.92 | W9: =+U9-V9 -> -0.025263158 | X9: =IFERROR(T9/S9-1,100%) -> -0.14285714 | Y9: 0.82 | Z9: =+U9/Y9-1 -> 0.09114249
B10: MO count | C10: 4 | D10: 9 | E10: 9 | F10: 0 | G10: 4 | H10: 5 | I10: 4 | J10: 5 | K10: 5 | L10: 2 | M10: 12 | N10: 1 | O10: 4 | P10: 3 | Q10: 2 | R10: 2 | S10: 1 | T10: 7 | U10: =SUM(O10:T10) -> 19 | Y10: 60
A11: OTIF 1st conf total | C11: 0.25 | D11: 0.57 | E11: 0.88 | F11: 0 | G11: 0.5 | H11: 0.5 | I11: 0.91 | J11: 1 | K11: 0.56 | L11: 1 | M11: 1 | N11: 1 | O11: 0.75 | P11: 0.58 | Q11: 0.95 | R11: 0.28 | S11: 0.71 | T11: 0.5 | U11: 0.62068966 | V11: 0.79 | W11: =+U11-V11 -> -0.16931034 | X11: =IFERROR(T11/S11-1,100%) -> -0.29577465 | Y11: 0.69 | Z11: =+U11/Y11-1 -> -0.10044978
A12: MO count total | C12: =SUM(C10,C8,C6) -> 28 | D12: =SUM(D10,D8,D6) -> 21 | E12: =SUM(E10,E8,E6) -> 32 | F12: =SUM(F10,F8,F6) -> 5 | G12: =SUM(G10,G8,G6) -> 26 | H12: =SUM(H10,H8,H6) -> 18 | I12: =SUM(I10,I8,I6) -> 32 | J12: =SUM(J10,J8,J6) -> 8 | ... U12: =SUM(U10,U8,U6) -> 116 | Y12: 263
A13: * It's agreed that all shipments in advance of the requested delivery date are accepted and don't create any negative signal to OTIF
A14: ** For OTIF only MOs not sent in time for MEL-T reasons are considered
A15: *** Shipment date + Transportation Lead Time ≤ Requested delivery date + 5 working days (agreed tolerance)
A16: Source: "OTIF_LT KPIs.xlsx"
A18: Lead Time (LT)
A19: LT Anticipo = Avvio - Partenza materiale // LT Produzione = Spedizione - Avvio // LT Totale End-to-End = Consegna - Partenza materiale
A20: BU | C20: 45688 | D20: 45716 | E20: 45747 | F20: 45777 | G20: 45777 | H20: 45838 | I20: 45869 | J20: 45900 | K20: 45930 | L20: 45961 | M20: 45991 | N20: 46022 | O20: 46053 | P20: 46081 | Q20: 46112 | R20: 46142 | S20: 46173 | T20: 46203 | U20: YTD | V20: TARGET | W20: +/- Vs trgt | X20: %Var. | Y20: MoM% | Z20: FY'25 | AA20: % Var. Vs FY'25
A21: Safety | B21: LT Anticipo | O21: 30 | P21: 28 | Q21: 82 | R21: 31 | S21: 54 | T21: 64.2 | U21: 45.520833 | V21: 90 | W21: =+U21-V21 -> -44.479167 | X21: =+U21/V21-1 -> -0.49421296 | Y21: =IFERROR(T21/S21-1,100%) -> 0.18888889
B22: LT Produzione | O22: 45 | P22: 55 | Q22: 30 | R22: 47 | S22: 27 | T22: 46.2 | U22: 41.5625 | V22: 30 | W22: =+U22-V22 -> 11.5625 | X22: =+U22/V22-1 -> 0.38541667 | Y22: =IFERROR(T22/S22-1,100%) -> 0.71111111
B23: LT End-to-End | O23: 78 | P23: 86 | Q23: 115 | R23: 81 | S23: 84 | T23: 114.4 | U23: 91.083333 | V23: 120 | W23: =+U23-V23 -> -28.916667 | X23: =+U23/V23-1 -> -0.24097222 | Y23: =IFERROR(T23/S23-1,100%) -> 0.36190476
A24: Leather | B24: LT Anticipo | O24: 16 | P24: 12 | Q24: 27 | R24: 51 | S24: 86 | T24: 43.714286 | U24: 34.714286 | V24: 90 | W24: =+U24-V24 -> -55.285714 | X24: =+U24/V24-1 -> -0.61428571 | Y24: =IFERROR(T24/S24-1,100%) -> -0.49169435
B25: LT Produzione | O25: 57 | P25: 76 | Q25: 67 | R25: 71 | S25: 66 | T25: 31.785714 | U25: 57.081633 | V25: 35 | W25: =+U25-V25 -> 22.081633 | X25: =+U25/V25-1 -> 0.63090379 | Y25: =IFERROR(T25/S25-1,100%) -> -0.51839827
B26: LT End-to-End | O26: 75 | P26: 91 | Q26: 97 | R26: 126 | S26: 155 | T26: 79.5 | U26: 95.795918 | V26: 125 | W26: =+U26-V26 -> -29.204082 | X26: =+U26/V26-1 -> -0.23363265 | Y26: =IFERROR(T26/S26-1,100%) -> -0.48709677
A27: D|air | B27: LT Anticipo | O27: 34 | P27: 47 | Q27: 81 | R27: 79 | S27: 69 | T27: 35.428571 | U27: 48.052632 | V27: 90 | W27: =+U27-V27 -> -41.947368 | X27: =+U27/V27-1 -> -0.46608187 | Y27: =IFERROR(T27/S27-1,100%) -> -0.48654244
B28: LT Produzione | O28: 31 | P28: 8 | Q28: 47 | R28: 35 | S28: 30 | T28: 17.571429 | U28: 24.315789 | V28: 15 | W28: =+U28-V28 -> 9.3157895 | X28: =+U28/V28-1 -> 0.62105263 | Y28: =IFERROR(T28/S28-1,100%) -> -0.41428571
B29: LT End-to-End | O29: 68 | P29: 58 | Q29: 130 | R29: 117 | S29: 102 | T29: 57 | U29: 76.368421 | V29: 105 | W29: =+U29-V29 -> -28.631579 | X29: =+U29/V29-1 -> -0.2726817 | Y29: =IFERROR(T29/S29-1,100%) -> -0.44117647
A30: LT Anticipo | O30: 25 | P30: 24 | Q30: 53 | R30: 42 | S30: 64 | T30: 45.423077 | U30: 41.37069 | V30: 90 | W30: =+U30-V30 -> -48.62931 | X30: =+U30/V30-1 -> -0.54032567 | Y30: =IFERROR(T30/S30-1,100%) -> -0.29026442
A31: LT Produzione | O31: 47 | P31: 56 | Q31: 51 | R31: 52 | S31: 38 | T31: 30.730769 | U31: 45.293103 | V31: 27 | W31: =+U31-V31 -> 18.293103 | X31: =+U31/V31-1 -> 0.67752235 | Y31: =IFERROR(T31/S31-1,100%) -> -0.19129555
A32: LT End-to-End | O32: 75 | P32: 84 | Q32: 107 | R32: 97 | S32: 106 | T32: 80.153846 | U32: 90.663793 | V32: 117 | W32: =+U32-V32 -> -26.336207 | X32: =+U32/V32-1 -> -0.22509579 | Y32: =IFERROR(T32/S32-1,100%) -> -0.24383164
A33: * LT Anticipo Pianificazione (gg): misura quanto stai anticipando quanto margine hai per ottimizzare trasporti
A34: ** LT Produzione: misura solo la parte interna efficienza fabbrica attese interne organizzazione
A35: *** LT End-to-End: è quello che il cliente “vive davvero”
A37: Service Level (SL) (in %)
A38: (Units sold of finished goods ÷ Budgeted units) × 100
A39: BU | C39: 45688 | D39: 45716 | E39: 45747 | F39: 45777 | G39: 45808 | H39: 45838 | I39: 45869 | J39: 45900 | K39: 45930 | L39: 45961 | M39: 45991 | N39: 46022 | O39: 46053 | P39: 46081 | Q39: 46112 | R39: 46142 | S39: 46173 | T39: 46203 | U39: YTD | V39: BDG | W39: +/- Vs bdg | X39: SL % | Y39: TARGET | Z39: %Var. Vs trgt | AA39: MoM% | AB39: PYTD | AC39: SL % FY'25 | AD39: YoY % | AE39: +/- SL Vs FY'25 | AF39: coda 2025 su 2026 | AG39: PLAN | AH39: +/- Vs pln | AI39: SL% Vs plan | AJ39: +/- Vs trgt | AL39: LM +/- Vs bdg | AM39: JUN Effect
A40: Safety | C40: 5638 | D40: 3715 | E40: 3194 | F40: 3425 | G40: 3102 | H40: 3170 | I40: 3939 | J40: 280 | K40: 3415 | L40: 3986 | M40: 5639 | N40: 2160 | O40: 4264 | P40: 2767 | Q40: 2252 | R40: 3232 | S40: 2300 | T40: 2003 | U40: =SUM(O40:T40) -> 16818 | V40: 25967 | W40: =+U40-V40 -> -9149 | X40: =IF(U40=0,"",(U40/V40)) -> 0.64766819 | Y40: 0.95 | Z40: =+X40/Y40-1 -> -0.31824401 | AA40: =IFERROR(T40/S40-1,100%) -> -0.12913043 | AB40: =SUM(C40:H40) -> 22244 | AC40: 0.81086394 | AD40: =IF(AB40=0,100%,U40/AB40-1) -> -0.24393095 | AE40: =+X40-AC40 -> -0.16319574 | AF40: -1537 | AH40: =+U40-AG40 -> 16818 | AI40: =IF(AG40=0,0,U40/AG40) -> 0 | AJ40: =IF(AG40=0,0,+AI40-Y40) -> 0 | AL40: -4222 | AM40: =+W40-AL40 -> -4927
A41: Leather | C41: 3500 | D41: 1499 | E41: 1449 | F41: 1381 | G41: 1487 | H41: 1697 | I41: 1481 | J41: 0 | K41: 1459 | L41: 2643 | M41: 1798 | N41: 573 | O41: 1812 | P41: 1149 | Q41: 1162 | R41: 961 | S41: 1536 | T41: 1706 | U41: =SUM(O41:T41) -> 8326 | V41: 9878 | W41: =+U41-V41 -> -1552 | X41: =IF(U41=0,"",(U41/V41)) -> 0.84288317 | Y41: 0.95 | Z41: =+X41/Y41-1 -> -0.11275455 | AA41: =IFERROR(T41/S41-1,100%) -> 0.11067708 | AB41: =SUM(C41:H41) -> 11013 | AC41: 0.97727741 | AD41: =IF(AB41=0,100%,U41/AB41-1) -> -0.24398438 | AE41: =+X41-AC41 -> -0.13439424 | AF41: -605 | AH41: =+U41-AG41 -> 8326 | AI41: =IF(AG41=0,0,U41/AG41) -> 0 | AJ41: =IF(AG41=0,0,+AI41-Y41) -> 0 | AL41: -1321 | AM41: =+W41-AL41 -> -231
A42: D|air | C42: 4358 | D42: 1723 | E42: 1283 | F42: 664 | G42: 1971 | H42: 904 | I42: 966 | J42: 620 | K42: 1420 | L42: 2182 | M42: 1950 | N42: 768 | O42: 1390 | P42: 816 | Q42: 877 | R42: 1076 | S42: 868 | T42: 1388 | U42: =SUM(O42:T42) -> 6415 | V42: 11271 | W42: =+U42-V42 -> -4856 | X42: =IF(U42=0,"",(U42/V42)) -> 0.56915979 | Y42: 0.95 | Z42: =+X42/Y42-1 -> -0.40088443 | AA42: =IFERROR(T42/S42-1,100%) -> 0.59907834 | AB42: =SUM(C42:H42) -> 10903 | AC42: 0.44674837 | AD42: =IF(AB42=0,100%,U42/AB42-1) -> -0.41162983 | AE42: =+X42-AC42 -> 0.12241142 | AF42: -325 | AH42: =+U42-AG42 -> 6415 | AI42: =IF(AG42=0,0,U42/AG42) -> 0 | AJ42: =IF(AG42=0,0,+AI42-Y42) -> 0 | AL42: -4344 | AM42: =+W42-AL42 -> -512
...

Sheet People
A1: Employee Retention & Productivity
A2: Overall Turnover rate (in %)
A3: (Terminations during period / Employees at period start) × 100
A4: BU | E4: 45838 | F4: 45869 | G4: 45900 | H4: 45930 | I4: 45961 | J4: 45991 | K4: 46022 | L4: 46053 | M4: 46081 | N4: 46112 | O4: 46142 | P4: 46173 | Q4: 46203 | R4: 46234 | S4: TARGET | T4: YoY%
A5: Safety | B5: Employees at Beginning | E5: 36 | F5: =+E5+E7+E8-E6 -> 36 | G5: =+F5+F7+F8-F6 -> 34 | H5: =+G5+G7+G8-G6 -> 34 | I5: =+H5+H7+H8-H6 -> 34 | J5: =+I5+I7+I8-I6 -> 33 | K5: =+J5+J7+J8-J6 -> 36 | L5: =+K5+K7+K8-K6 -> 34 | M5: =+L5+L7+L8-L6 -> 27 | ... R5: =+Q5+Q7+Q8-Q6 -> 32
A6: Safety | B6: Terminations | E6: 1 | F6: 4 | G6: 0 | H6: 2 | I6: 2 | J6: 2 | K6: 2 | L6: 8 | M6: 2 | N6: 3 | O6: 1 | P6: 1 | Q6: 0
A7: Safety | B7: Hires | E7: 1 | F7: 2 | G7: 0 | H7: 2 | I7: 2 | J7: 2 | K7: 0 | L7: 2 | M7: 4 | N7: 0 | O7: 3 | P7: 0 | Q7: 4
A8: Safety | B8: Spostamenti interni | E8: 0 | F8: 0 | G8: 0 | H8: 0 | I8: -1 | J8: 3 | K8: 0 | L8: -1 | M8: 1 | N8: 0 | O8: 0 | P8: 0 | Q8: 0
A9: Safety | D9: Turnover rate | E9: =+E6/E5 -> 0.027777778 | F9: =+F6/F5 -> 0.11111111 | G9: =+G6/G5 -> 0 | H9: =+H6/H5 -> 0.058823529 | I9: =+I6/I5 -> 0.058823529 | J9: =+J6/J5 -> 0.060606061 | K9: =+K6/K5 -> 0.055555556 | L9: =+L6/L5 -> 0.23529412 | ... R9: =+R6/R5 -> 0
A10: Safety | D10: YTD | E10: 0.27384077 | F10: 0.38495188 | G10: 0.38495188 | H10: 0.44377541 | I10: 0.50259894 | J10: 0.563205 | K10: 0.61876055 | L10: =+L9 -> 0.23529412 | M10: =+M9+L10 -> 0.30936819 | N10: =+N9+M10 -> 0.40936819 | O10: =+O9+N10 -> 0.44640523 | P10: =+P9+O10 -> 0.48088799 | Q10: =+Q9+P10 -> 0.48088799 | R10: =+R9+Q10 -> 0.48088799 | S10: YTD<-10pts vs PY | T10: =IFERROR(Q10/E10-1,100%) -> 0.75608618
A11: Leather | B11: Employees at Beginning | E11: 98 | F11: =+E11+E13+E14-E12 -> 99 | G11: =+F11+F13+F14-F12 -> 97 | H11: =+G11+G13+G14-G12 -> 98 | I11: =+H11+H13+H14-H12 -> 102 | J11: =+I11+I13+I14-I12 -> 103 | K11: =+J11+J13+J14-J12 -> 101 | L11: =+K11+K13+K14-K12 -> 100 | M11: =+L11+L13+L14-L12 -> 94 | ... R11: =+Q11+Q13+Q14-Q12 -> 96
A12: Leather | B12: Terminations | E12: 0 | F12: 2 | G12: 0 | H12: 3 | I12: 1 | J12: 3 | K12: 1 | L12: 4 | M12: 1 | N12: 2 | O12: 2 | P12: 0 | Q12: 1
A13: Leather | B13: Hires | E13: 1 | F13: 0 | G13: 0 | H13: 6 | I13: 2 | J13: 3 | K13: 0 | L13: 1 | M13: 1 | N13: 0 | O13: 2 | P13: 1 | Q13: 3
A14: Leather | B14: Spostamenti interni | E14: 0 | F14: 0 | G14: 1 | H14: 1 | I14: 0 | J14: -2 | K14: 0 | L14: -3 | M14: 0 | N14: 0 | O14: 0 | P14: 1 | Q14: 0
A15: Leather | D15: Turnover rate | E15: =+E12/E11 -> 0 | F15: =+F12/F11 -> 0.02020202 | G15: =+G12/G11 -> 0 | H15: =+H12/H11 -> 0.030612245 | I15: =+I12/I11 -> 0.0098039216 | J15: =+J12/J11 -> 0.029126214 | K15: =+K12/K11 -> 0.0099009901 | L15: =+L12/L11 -> 0.04 | ... R15: =+R12/R11 -> 0
A16: Leather | D16: YTD | E16: 0.10954129 | F16: 0.12974331 | G16: 0.12974331 | H16: 0.16035555 | I16: 0.17015947 | J16: 0.19928569 | K16: 0.20918668 | L16: =+L15 -> 0.04 | M16: =+M15+L16 -> 0.050638298 | N16: =+N15+M16 -> 0.071914894 | O16: =+O15+N16 -> 0.093654024 | P16: =+P15+O16 -> 0.093654024 | Q16: =+Q15+P16 -> 0.10429232 | R16: =+R15+Q16 -> 0.10429232 | S16: YTD<-10pts vs PY | T16: =IFERROR(Q16/E16-1,100%) -> -0.047917669
A17: Dair | B17: Employees at Beginning | E17: 13 | F17: =+E17+E19+E20-E18 -> 14 | G17: =+F17+F19+F20-F18 -> 14 | H17: =+G17+G19+G20-G18 -> 13 | I17: =+H17+H19+H20-H18 -> 11 | J17: =+I17+I19+I20-I18 -> 12 | K17: =+J17+J19+J20-J18 -> 11 | L17: =+K17+K19+K20-K18 -> 11 | M17: =+L17+L19+L20-L18 -> 9 | ... R17: =+Q17+Q19+Q20-Q18 -> 8
A18: Dair | B18: Terminations | E18: 0 | F18: 1 | G18: 0 | H18: 1 | I18: 1 | J18: 0 | K18: 0 | L18: 1 | M18: 0 | N18: 0 | O18: 0 | P18: 0 | Q18: 0
A19: Dair | B19: Hires | E19: 1 | F19: 1 | G19: 0 | H19: 0 | I19: 1 | J19: 0 | K19: 0 | L19: 0 | M19: 0 | N19: 0 | O19: 0 | P19: 0 | Q19: 0
A20: Dair | B20: Spostamenti interni | E20: 0 | F20: 0 | G20: -1 | H20: -1 | I20: 1 | J20: -1 | K20: 0 | L20: -1 | M20: 0 | N20: 0 | O20: 0 | P20: -1 | Q20: 0
A21: Dair | D21: Turnover rate | E21: =+E18/E17 -> 0 | F21: =+F18/F17 -> 0.071428571 | G21: =+G18/G17 -> 0 | H21: =+H18/H17 -> 0.076923077 | I21: =+I18/I17 -> 0.090909091 | J21: =+J18/J17 -> 0 | K21: =+K18/K17 -> 0 | L21: =+L18/L17 -> 0.090909091 | ... R21: =+R18/R17 -> 0
A22: Dair | D22: YTD | E22: 0.33501401 | F22: 0.40644258 | G22: 0.40644258 | H22: 0.48336565 | I22: 0.57427474 | J22: 0.57427474 | K22: 0.57427474 | L22: =+L21 -> 0.090909091 | M22: =+M21+L22 -> 0.090909091 | N22: =+N21+M22 -> 0.090909091 | O22: =+O21+N22 -> 0.090909091 | P22: =+P21+O22 -> 0.090909091 | Q22: =+Q21+P22 -> 0.090909091 | R22: =+R21+Q22 -> 0.090909091 | S22: YTD<-10pts vs PY | T22: =IFERROR(Q22/E22-1,100%) -> -0.72864092
A23: Commun | B23: Employees at Beginning | E23: 16 | F23: =+E23+E25+E26-E24 -> 16 | G23: =+F23+F25+F26-F24 -> 17 | H23: =+G23+G25+G26-G24 -> 17 | I23: =+H23+H25+H26-H24 -> 17 | J23: =+I23+I25+I26-I24 -> 16 | K23: =+J23+J25+J26-J24 -> 14 | L23: =+K23+K25+K26-K24 -> 14 | M23: =+L23+L25+L26-L24 -> 20 | ... R23: =+Q23+Q25+Q26-Q24 -> 19
A24: Commun | B24: Terminations | E24: 0 | F24: 0 | G24: 0 | H24: 0 | I24: 2 | J24: 2 | K24: 0 | L24: 0 | M24: 1 | N24: 0 | O24: 1 | P24: 0 | Q24: 1
A25: Commun | B25: Hires | E25: 0 | F25: 1 | G25: 0 | H25: 0 | I25: 1 | J25: 0 | K25: 0 | L25: 1 | M25: 1 | N25: 0 | O25: 0 | P25: 0 | Q25: 2
A26: Commun | B26: Spostamenti interni | E26: 0 | F26: 0 | G26: 0 | H26: 0 | I26: 0 | J26: 0 | K26: 0 | L26: 5 | M26: -1 | N26: 0 | O26: 0 | P26: 0 | Q26: 0
A27: Commun | D27: Turnover rate | E27: =+E24/E23 -> 0 | F27: =+F24/F23 -> 0 | G27: =+G24/G23 -> 0 | H27: =+H24/H23 -> 0 | I27: =+I24/I23 -> 0.11764706 | J27: =+J24/J23 -> 0.125 | K27: =+K24/K23 -> 0 | L27: =+L24/L23 -> 0 | ... R27: =+R24/R23 -> 0
A28: Commun | D28: YTD | E28: 0.058823529 | F28: 0.058823529 | G28: 0.058823529 | H28: 0.058823529 | I28: 0.17647059 | J28: 0.30147059 | K28: 0.30147059 | L28: =+L27 -> 0 | M28: =+M27+L28 -> 0.05 | N28: =+N27+M28 -> 0.05 | O28: =+O27+N28 -> 0.10263158 | P28: =+P27+O28 -> 0.10263158 | Q28: =+Q27+P28 -> 0.15818713 | R28: =+R27+Q28 -> 0.15818713 | S28: YTD<-10pts vs PY | T28: =IFERROR(Q28/E28-1,100%) -> 1.6891813
A29: MEL-T | B29: Employees at Beginning | E29: 163 | F29: =+E29+E31+E32-E30 -> 165 | G29: =+F29+F31+F32-F30 -> 162 | H29: =+G29+G31+G32-G30 -> 162 | I29: =+H29+H31+H32-H30 -> 164 | J29: =+I29+I31+I32-I30 -> 164 | K29: =+J29+J31+J32-J30 -> 162 | L29: =+K29+K31+K32-K30 -> 159 | M29: =+L29+L31+L32-L30 -> 150 | ... R29: =+Q29+Q31+Q32-Q30 -> 155
A30: MEL-T | B30: Terminations | E30: =SUM(E24,E18,E12,E6) -> 1 | F30: =SUM(F24,F18,F12,F6) -> 7 | G30: =SUM(G24,G18,G12,G6) -> 0 | H30: =SUM(H24,H18,H12,H6) -> 6 | I30: =SUM(I24,I18,I12,I6) -> 6 | J30: =SUM(J24,J18,J12,J6) -> 7 | K30: =SUM(K24,K18,K12,K6) -> 3 | L30: =SUM(L24,L18,L12,L6) -> 13 | ... R30: =SUM(R24,R18,R12,R6) -> 0
A31: MEL-T | B31: Hires | E31: =SUM(E25,E19,E13,E7) -> 3 | F31: =SUM(F25,F19,F13,F7) -> 4 | G31: =SUM(G25,G19,G13,G7) -> 0 | H31: =SUM(H25,H19,H13,H7) -> 8 | I31: =SUM(I25,I19,I13,I7) -> 6 | J31: =SUM(J25,J19,J13,J7) -> 5 | K31: =SUM(K25,K19,K13,K7) -> 0 | L31: =SUM(L25,L19,L13,L7) -> 4 | ... R31: =SUM(R25,R19,R13,R7) -> 0
A32: MEL-T | B32: Spostamenti interni | E32: =SUM(E26,E20,E14,E8) -> 0 | F32: =SUM(F26,F20,F14,F8) -> 0 | G32: =SUM(G26,G20,G14,G8) -> 0 | H32: =SUM(H26,H20,H14,H8) -> 0 | I32: =SUM(I26,I20,I14,I8) -> 0 | J32: =SUM(J26,J20,J14,J8) -> 0 | K32: =SUM(K26,K20,K14,K8) -> 0 | L32: =SUM(L26,L20,L14,L8) -> 0 | ... R32: =SUM(R26,R20,R14,R8) -> 0
A33: MEL-T | D33: Turnover rate | E33: =+E30/E29 -> 0.0061349693 | F33: =+F30/F29 -> 0.042424242 | G33: =+G30/G29 -> 0 | H33: =+H30/H29 -> 0.037037037 | I33: =+I30/I29 -> 0.036585366 | J33: =+J30/J29 -> 0.042682927 | K33: =+K30/K29 -> 0.018518519 | L33: =+L30/L29 -> 0.081761006 | ... R33: =+R30/R29 -> 0
A34: MEL-T | D34: YTD | E34: 0.16418943 | F34: 0.20661368 | G34: 0.20661368 | H34: 0.24365071 | I34: 0.28023608 | J34: 0.32291901 | K34: 0.34143753 | L34: =+L33 -> 0.081761006 | M34: =+M33+L34 -> 0.10842767 | N34: =+N33+M34 -> 0.14132241 | O34: =+O33+N34 -> 0.16853329 | P34: =+P33+O34 -> 0.17529005 | Q34: =+Q33+P34 -> 0.18880356 | R34: =+R33+Q34 -> 0.18880356 | S34: YTD<-10 p.p. vs PY | T34: =IFERROR(Q34/E34-1,100%) -> 0.149913
A35: Source: « Rolling Turnover rate.xlsx"
A38: Absenteeism Rate (in %)
A39: (Unplanned Lost Hours / Available Hours) × 100
D40: MONTH MAG'26 | L40: YTD'26 | V40: MONTH | AB40: YTD | AI40: BDG | AL40: +/- Vs bdg
A41: BU | D41: Available Hrs | E41: Overall absence Hrs | F41: Overal Absene Rate | G41: Absenteeism Hrs | H41: Absenteeism Rate | I41: TARGET | J41: +/- Vs trgt | L41: Available Hrs | M41: Overall absence Hrs | N41: Overal Absene Rate | O41: Absenteeism Hrs | P41: Absenteeism Rate | Q41: TARGET | R41: +/- Vs trgt | S41: FY'25 | T41: % Var. Vs FY'25 | V41: Hrs par 1.0FTE | W41: Average HC | X41: Absence FTE | Y41: 1.0 FTE | Z41: % | AB41: Hrs par 1.0FTE | AC41: Average HC | AD41: Absence FTE | AE41: 1.0 FTE | AF41: % | AH41: ACT HC | AI41: HC | AJ41: 1.0 FTE | AK41: % | AL41: HC | AM41: 1.0 FTE | AN41: % | AP41: Hire budget realisation | AQ41: To Hire | AR41: % | AS41: Ratio Abs vs BDG
A42: Safety | D42: 4922.5 | E42: 1181 | F42: =+E42/D42 -> 0.23991874 | G42: 1085.5 | H42: =+G42/D42 -> 0.22051803 | I42: 0.075 | J42: =H42-I42 -> 0.14551803 | L42: 27484.5 | M42: 7124 | N42: =+M42/L42 -> 0.25920064 | O42: 5418.5 | P42: =+O42/L42 -> 0.19714748 | Q42: 0.075 | R42: =P42-Q42 -> 0.12214748 | S42: 0.10604721 | T42: =P42/S42-1 -> 0.85905395 | V42: 193.5 | W42: =+D42/V42 -> 25.439276 | X42: =+E42/V42 -> 6.1033592 | Y42: =+W42-X42 -> 19.335917 | Z42: =+Y42/W42-1 -> -0.23991874 | AB42: 1105 | AC42: =+L42/AB42 -> 24.872851 | AD42: =+M42/AB42 -> 6.4470588 | AE42: =+AC42-AD42 -> 18.425792 | AF42: =+AE42/AC42-1 -> -0.25920064 | AH42: 26 | AI42: 44 | AJ42: 35.58 | AK42: =+AJ42/AI42-1 -> -0.19136364 | AL42: =+AH42-AI42 -> -18 | AM42: =+AE42-AJ42 -> -17.154208 | AN42: =-AF42+AK42 -> 0.067837004 | AP42: =+AH42/AI42 -> 0.59090909 | AQ42: =+AM42*(1+AN42) -> -18.317898 | AR42: =AQ42/AI42 -> -0.41631587 | AS42: =+AF42/AK42 -> 1.3544927
...

Sheet People_2
A1: Mth | B1: HC (inizio mese) | C1: HIRE | D1: LEFT | E1: DIR → IND | F1: IND →DIR | G1: HC (fine mese) | H1: Bdg / Trgt | I1: % Realization | J1: +/- Vs BDG | K1: Note
A2: gen | B2: 120 | C2: 2 | D2: 10 | G2: =+B2+C2-D2-E2+F2 -> 112 | H2: 120 | I2: =+G2/H2 -> 0.93333333 | J2: =+G2-H2 -> -8
A3: feb | B3: =+G2 -> 112 | C3: 4 | D3: 3 | G3: =+B3+C3-D3-E3+F3 -> 113 | H3: 120 | I3: =+G3/H3 -> 0.94166667 | J3: =+G3-H3 -> -7
A4: mar | B4: =+G3 -> 113 | C4: 0 | D4: 5 | E4: 1 | G4: =+B4+C4-D4-E4+F4 -> 107 | H4: 123 | I4: =+G4/H4 -> 0.8699187 | J4: =+G4-H4 -> -16 | K4: changement Mat 1712 de taglio Pelle Vers Warehouse
A5: apr | B5: =+G4 -> 107 | C5: 4 | D5: 3 | G5: =+B5+C5-D5-E5+F5 -> 108 | H5: 129 | I5: =+G5/H5 -> 0.8372093 | J5: =+G5-H5 -> -21
A6: mag | B6: =+G5 -> 108 | C6: 1 | G6: =+B6+C6-D6-E6+F6 -> 109 | H6: 134 | I6: =+G6/H6 -> 0.81343284 | J6: =+G6-H6 -> -25
A7: giu | B7: =+G6 -> 109 | C7: 7 | D7: 1 | E7: 1 | F7: 1 | G7: =+B7+C7-D7-E7+F7 -> 115 | H7: 135 | I7: =+G7/H7 -> 0.85185185 | J7: =+G7-H7 -> -20 | K7: Changement Mat 719 de Maintenance Vers TGL Laser + Changement Mat 369 vers Line Leader
A8: lug | B8: =+G7 -> 115 | G8: =+B8+C8-D8-E8+F8 -> 115 | H8: 135 | I8: =+G8/H8 -> 0.85185185 | J8: =+G8-H8 -> -20
A9: ago | B9: =+G8 -> 115 | G9: =+B9+C9-D9-E9+F9 -> 115 | H9: 135 | I9: =+G9/H9 -> 0.85185185 | J9: =+G9-H9 -> -20
A10: set | B10: =+G9 -> 115 | G10: =+B10+C10-D10-E10+F10 -> 115 | H10: 135 | I10: =+G10/H10 -> 0.85185185 | J10: =+G10-H10 -> -20
A11: ott | B11: =+G10 -> 115 | G11: =+B11+C11-D11-E11+F11 -> 115 | H11: 135 | I11: =+G11/H11 -> 0.85185185 | J11: =+G11-H11 -> -20
A12: nov | B12: =+G11 -> 115 | G12: =+B12+C12-D12-E12+F12 -> 115 | H12: 135 | I12: =+G12/H12 -> 0.85185185 | J12: =+G12-H12 -> -20
A13: dic | B13: =+G12 -> 115 | G13: =+B13+C13-D13-E13+F13 -> 115 | H13: 135 | I13: =+G13/H13 -> 0.85185185 | J13: =+G13-H13 -> -20

Sheet Worked Hrs
B1: Total worked hours and Overtime by Month
A3: Grand total | B3: Valori | C3: 45688 | D3: 45716 | E3: 45747 | F3: 45777 | G3: 45808 | H3: 45838 | I3: 45869 | J3: 45900 | K3: 45930 | L3: 45961 | M3: 45991 | N3: 46022 | O3: 46053 | P3: 46081 | Q3: 46112 | R3: 46142 | S3: 46173 | T3: 46203
A4: =SUM(O4:Z4) -> 168623 | B4: Available Hours | C4: 35186 | D4: 31851.5 | E4: 28203 | F4: 31774.5 | G4: 32422.5 | H4: 28239 | I4: 33153.5 | J4: 10444.5 | K4: 31287 | L4: 34724.5 | M4: 30948 | N4: 32506.5 | O4: 30654 | P4: 27728 | Q4: 24817.5 | R4: 30334.5 | S4: 25010 | T4: 30079
A5: =SUM(O5:Z5) -> 142970 | B5: Worked Hours (Regular Hrs) | C5: 30578 | D5: 27764 | E5: 19899 | F5: 18771 | G5: 23784 | H5: 23249 | I5: 28405.5 | J5: 6313.5 | K5: 26257.5 | L5: 29561.5 | M5: 25807.5 | N5: 24668 | O5: 23842 | P5: 23490.5 | Q5: 21026 | R5: 26516 | S5: 21892.5 | T5: 26203
A6: =SUM(O6:Z6) -> 923 | B6: HC | C6: 179 | D6: 177 | E6: 174 | F6: 167 | G6: 164 | H6: 165 | I6: 168 | J6: 161 | K6: 169 | L6: 169 | M6: 168 | N6: 161 | O6: 162 | P6: 155 | Q6: 151 | R6: 151 | S6: 148 | T6: 156
A7: =SUM(O7:Z7) -> 1105 | B7: Hrs par 1.0FTE | C7: 202 | D7: 185 | E7: 168 | F7: 195.5 | G7: 201 | H7: 169 | I7: 202 | J7: 58.5 | K7: 191.5 | L7: 210.5 | M7: 185 | N7: 202 | O7: 201 | P7: 178 | Q7: 164.5 | R7: 202 | S7: 166 | T7: 193.5
A8: =SUM(O8:Z8) -> 776.96952 | B8: 1.0 FTE | C8: 151.37624 | D8: 150.07568 | E8: 118.44643 | F8: 96.015345 | G8: 118.32836 | H8: 137.56805 | I8: 140.62129 | J8: 107.92308 | K8: 137.11488 | L8: 140.43468 | M8: 139.5 | N8: 122.11881 | O8: 118.61692 | P8: 131.9691 | Q8: 127.81763 | R8: 131.26733 | S8: 131.88253 | T8: 135.41602
A9: =SUM(O9:Z9) -> 219.5 | B9: 1.00x OT Hrs | C9: 0 | D9: 1.5 | E9: 220.5 | F9: 609.5 | G9: 87.5 | H9: 4.5 | I9: 1 | J9: 218.5 | K9: 24.5 | L9: 46.5 | M9: 24 | N9: 0 | O9: 60.5 | P9: 31 | Q9: 0 | R9: 0 | S9: 3 | T9: 125
A10: =SUM(O10:Z10) -> 1174 | B10: 1.75x OT Hrs | C10: 7.5 | D10: 24 | E10: 0 | F10: 28.5 | G10: 38.5 | H10: 0 | I10: 0 | J10: 206 | K10: 129 | L10: 179 | M10: 75 | N10: 0 | O10: 7 | P10: 40 | Q10: 0 | R10: 30 | S10: 392 | T10: 705
A11: =SUM(O11:Z11) -> 435.5 | B11: 2.00x OT Hrs | C11: 64 | D11: 5 | E11: 5 | F11: 10.5 | H11: 245.5 | I11: 48 | J11: 57.5 | K11: 71.5 | L11: 5.5 | M11: 11.5 | N11: 36 | O11: 44 | Q11: 96 | R11: 20 | S11: 165.5 | T11: 110
A12: =SUM(O12:Z12) -> 144799 | B12: Total Worked Hours | C12: 30649.5 | D12: 27794.5 | E12: 20124.5 | F12: 19419.5 | G12: 23910 | H12: 23499 | I12: 28454.5 | J12: 6795.5 | K12: 26482.5 | L12: 29792.5 | M12: 25918 | N12: 24704 | O12: 23953.5 | P12: 23561.5 | Q12: 21122 | R12: 26566 | S12: 22453 | T12: 27143
A13: =SUM(O13:Z13) -> 1829 | B13: Total Overtime Hrs | C13: 71.5 | D13: 30.5 | E13: 225.5 | F13: 648.5 | G13: 126 | H13: 250 | I13: 49 | J13: 482 | K13: 225 | L13: 231 | M13: 110.5 | N13: 36 | O13: 111.5 | P13: 71 | Q13: =SUM(Q9:Q11) -> 96 | R13: =SUM(R9:R11) -> 50 | S13: 560.5 | T13: 940
A14: =+A13/A12 -> 0.012631303 | B14: OT rate | C14: 0.0023328276 | D14: 0.0010973394 | E14: 0.011205247 | F14: 0.033394269 | G14: 0.0052697616 | H14: 0.010638751 | I14: 0.0017220475 | J14: 0.070929291 | K14: 0.0084961767 | L14: 0.0077536293 | M14: 0.0042634463 | N14: 0.0014572539 | O14: 0.0046548521 | P14: 0.0030133905 | Q14: =+Q13/Q12 -> 0.0045450241 | R14: =+R13/R12 -> 0.0018821049 | S14: 0.024963257 | T14: 0.034631397
B17: Absence hours by Type, Type level, Reasons and Month [ Only DL ]
A19: Grand total | B19: Valori | C19: 45688 | D19: 45716 | E19: 45747 | F19: 45777 | G19: 45808 | H19: 45838 | I19: 45869 | J19: 45900 | K19: 45930 | L19: 45961 | M19: 45991 | N19: 46022 | O19: 46053 | P19: 46081 | Q19: 46112 | R19: 46142 | S19: 46173 | T19: 46203
A20: =SUM(O20:Z20) -> 123069 | B20: Available Hours | C20: 27679 | D20: 25191.5 | E20: 22155 | F20: 24541 | G20: 24985.5 | H20: 21106.5 | I20: 24743.5 | J20: 7020 | K20: 23181 | L20: 25957.5 | M20: 22978.5 | N20: 24366.5 | O20: 22854.5 | P20: 20334 | Q20: 17848 | R20: 21908.5 | S20: 18077 | T20: 22047
A21: =SUM(O21:Z21) -> 100979.5 | B21: Worked Hours | C21: 23742.5 | D21: 21530 | E21: 15443.5 | F21: 14258.5 | G21: 18071.5 | H21: 17104.5 | I21: 20753.5 | J21: 3709 | K21: 18966.5 | L21: 21665 | M21: 18669.5 | N21: 17851.5 | O21: 17164 | P21: 16630.5 | Q21: 14580.5 | R21: 18571 | S21: 15397.5 | T21: 18636
A22: =SUM(O22:Z22) -> 686 | B22: HC | C22: 141 | D22: 141 | E22: 138 | F22: 130 | G22: 127 | H22: 125 | I22: 125 | J22: 120 | K22: 128 | L22: 127 | M22: 127 | N22: 123 | O22: 122 | P22: 116 | Q22: 112 | R22: 111 | S22: 109 | T22: 116
A23: =SUM(O23:Z23) -> -22089.5 | B23: Overall Absence Hours | C23: -3936.5 | D23: -3661.5 | E23: -6711.5 | F23: -10282.5 | G23: -6914 | H23: -4002 | I23: -3990 | J23: -3311 | K23: -4214.5 | L23: -4292.5 | M23: -4309 | N23: -6515 | O23: -5690.5 | P23: -3703.5 | Q23: -3267.5 | R23: -3337.5 | S23: -2679.5 | T23: -3411
A24: =SUM(O24:Z24) -> 1.0694754 | B24: Overall Absence Rate | C24: 0.14221973 | D24: 0.14534664 | E24: 0.30293387 | F24: 0.41899271 | G24: 0.2767205 | H24: 0.18960984 | I24: 0.16125447 | J24: 0.47165242 | K24: 0.18180838 | L24: 0.16536646 | M24: 0.18752312 | N24: 0.26737529 | O24: 0.24898816 | P24: 0.18213337 | Q24: 0.18307373 | R24: 0.15233813 | S24: 0.14822703 | T24: 0.15471493
A25: =SUM(O25:Z25) -> 1105 | B25: Hrs par 1.0FTE | C25: 202 | D25: 185 | E25: 168 | F25: 195.5 | G25: 201 | H25: 169 | I25: 202 | J25: 58.5 | K25: 191.5 | L25: 210.5 | M25: 185 | N25: 202 | O25: 201 | P25: 178 | Q25: 164.5 | R25: 202 | S25: 166 | T25: 193.5
A26: =SUM(O26:Z26) -> 548.45981 | B26: 1.0 FTE | C26: 117.53713 | D26: 116.37838 | E26: 91.925595 | F26: 72.933504 | G26: 89.90796 | H26: 101.21006 | I26: 102.7401 | J26: 63.401709 | K26: 99.041775 | L26: 102.92162 | M26: 100.91622 | N26: 88.373762 | O26: 85.393035 | P26: 93.429775 | Q26: 88.635258 | R26: 91.935644 | S26: 92.756024 | T26: 96.310078
A27: =SUM(O27:Z27) -> 5637.5 | B27: 1000 - Planned and approved | C27: 230.5 | D27: 266.5 | E27: 444.5 | F27: 513.5 | G27: 1045.5 | H27: 755.5 | I27: 737.5 | J27: 322.5 | K27: 509.5 | L27: 843.5 | M27: 895 | N27: 905 | O27: 603 | P27: 847.5 | Q27: 1023 | R27: 1173.5 | S27: 937 | T27: 1053.5
A28: =SUM(O28:Z28) -> 3169 | B28: 2000 - Planned and unapproved | C28: 1735 | D28: 986 | E28: 4868 | F28: 7480 | G28: 4153 | H28: 1502.5 | I28: 1396 | J28: 2562.5 | K28: 1268 | L28: 1117 | M28: 1598.5 | N28: 3093 | O28: 1553.5 | P28: 93 | Q28: 477.5 | R28: 373.5 | S28: 483 | T28: 188.5
A29: =SUM(O29:Z29) -> 2651.5 | B29: 3000 - Unplanned and unapproved | C29: 980 | D29: 837.5 | E29: 370 | F29: 373 | G29: 210 | H29: 454.5 | I29: 455.5 | J29: 56 | K29: 360 | L29: 496 | M29: 507 | N29: 445 | O29: 871 | P29: 339.5 | Q29: 274.5 | R29: 336 | S29: 222.5 | T29: 608
A30: =SUM(O30:Z30) -> 10631.5 | B30: 4000 - Unplanned and approved | C30: 991 | D30: 1571.5 | E30: 1029 | F30: 1916 | G30: 1505.5 | H30: 1289.5 | I30: 1401 | J30: 370 | K30: 2077 | L30: 1836 | M30: 1308.5 | N30: 2072 | O30: 2663 | P30: 2423.5 | Q30: 1492.5 | R30: 1454.5 | S30: 1037 | T30: 1561
A32: =SUM(O32:Z32) -> 13283 | B32: Absenteeism Hrs | C32: 1971 | D32: 2409 | E32: 1399 | F32: 2289 | G32: 1715.5 | H32: 1744 | I32: 1856.5 | J32: 426 | K32: 2437 | L32: 2332 | M32: 1815.5 | N32: 2517 | O32: 3534 | P32: 2763 | Q32: 1767 | R32: 1790.5 | S32: 1259.5 | T32: 2169
A33: =+A32/A20 -> 0.10793132 | B33: Absenteeism Rate | C33: 0.07120922 | D33: 0.095627493 | E33: 0.063146017 | F33: 0.093272483 | G33: 0.068659823 | H33: 0.082628574 | I33: 0.075029806 | J33: 0.060683761 | K33: 0.1051292 | L33: 0.08983916 | M33: 0.079008639 | N33: 0.10329756 | O33: 0.15463038 | P33: 0.13588079 | Q33: 0.099002689 | R33: 0.081726271 | S33: 0.069674172 | T33: 0.098380732
B35: Total worked hours and Overtime by Month
B37: Valori | C37: 45688 | D37: 45716 | E37: 45747 | F37: 45777 | G37: 45808 | H37: 45838 | I37: 45869 | J37: 45900 | K37: 45930 | L37: 45961 | M37: 45991 | N37: 46022 | O37: 46053 | P37: 46081 | Q37: 46112 | R37: 46142 | S37: 46173 | T37: 46203
A38: =SUM(O38:Z38) -> 150652.5 | B38: Payable Hours | C38: 31640 | D38: 27545 | E38: 22460 | F38: 20550 | G38: 24940.5 | H38: 26254 | I38: 29251.5 | J38: 6538.5 | K38: 27199 | L38: 29367.5 | M38: 25509.5 | N38: 28336.5 | O38: 24926 | P38: 23688 | Q38: 22906 | R38: 26452.5 | S38: 25268.5 | T38: 27411.5
A39: =SUM(O39:Z39) -> 142970 | B39: Worked Hours (Regular Hrs) | C39: 30578 | D39: 27764 | E39: 19899 | F39: 18771 | G39: 23784 | H39: 23249 | I39: 28405.5 | J39: 6313.5 | K39: 26257.5 | L39: 29561.5 | M39: 25807.5 | N39: 24668 | O39: 23842 | P39: 23490.5 | Q39: 21026 | R39: 26516 | S39: 21892.5 | T39: 26203
A40: =SUM(O40:Z40) -> 7024 | B40: AL12 - Jours fériés, chômés et payés | C40: 1275 | E40: 2440 | F40: 1160 | G40: 1136 | H40: 3192 | I40: 1048 | K40: 1088 | N40: 1112 | O40: 1104 | Q40: 1968 | S40: 2952 | T40: 1000
A41: =SUM(O41:Z41) -> 119 | B41: AL23 - Congés spéciaux pour raison de famille | C41: 67 | D41: 25.5 | E41: 0 | F41: 76.5 | G41: 8.5 | H41: 59.5 | I41: 51 | J41: 25.5 | K41: 25.5 | L41: 34 | M41: 17 | N41: 42.5 | O41: 42.5 | P41: 25.5 | Q41: 0 | R41: 25.5 | S41: 0 | T41: 25.5
A42: =SUM(O42:Z42) -> 0 | B42: AT39 - Chômage partiel payés | C42: 85 | D42: 0 | E42: 0 | F42: 0 | G42: 0 | H42: 0 | I42: 0 | J42: 0 | K42: 0 | L42: 0 | M42: 0 | N42: 0 | O42: 0 | P42: 0 | Q42: 0 | R42: 0 | S42: 0 | T42: 0
A43: =SUM(O43:Z43) -> 459 | B43: AT39 - Chômage partiel payés (H) | Q43: 72 | S43: 387
A44: =SUM(O44:Z44) -> 68 | B44: AT40 - Participation à la formation | C44: 0 | D44: 0 | E44: 0 | F44: 0 | G44: 0 | H44: 0 | I44: 0 | J44: 0 | K44: 0 | L44: 0 | M44: 0 | N44: 0 | O44: 17 | P44: 0 | Q44: 0 | R44: 34 | S44: 0 | T44: 17
A45: =SUM(O45:Z45) -> 345 | B45: AT40 - Participation à la formation (H) | M45: 36 | N45: 18 | O45: 12 | S45: 134 | T45: 199
A46: =SUM(O46:Z46) -> 219.5 | B46: 1.00x OT Hrs | C46: 0 | D46: 1.5 | E46: 220.5 | F46: 609.5 | G46: 87.5 | H46: 4.5 | I46: 1 | J46: 218.5 | K46: 24.5 | L46: 46.5 | M46: 24 | N46: 0 | O46: 60.5 | P46: 31 | Q46: 0 | R46: 0 | S46: 3 | T46: 125
A47: =SUM(O47:Z47) -> 22 | B47: 1.25x OT Hrs | C47: 54 | D47: 22 | F47: 10 | G47: 13 | H47: 76 | I47: 8 | L47: 28 | M47: 2 | T47: 22
...

Sheet Quality
A1: Apparel Quality Rate
A2: Apparel - FQC Defective Rate Finished Goods
A3: (Defective Units / Units Inspected) × 100
B5: MONTH JUN'26 | J5: YTD'26
A6: BU | B6: Qty prod | C6: Sample size | D6: Check Rate | E6: Defective units | F6: FQC Rej % | G6: TARGET | H6: +/- Vs trgt | J6: Qty prod | K6: Sample size | L6: Check Rate | M6: Defective units | N6: FQC Rej % | O6: % Yiled FQR | P6: % FPY | Q6: TARGET | R6: % Var. Vs trgt | T6: FY'25 | U6: % Var. Vs PY | W6: # Opportunities | X6: # Defects | Y6: DPU | Z6: DPR | AA6: Throughput Yield TPY | AB6: DPO | AC6: DPMO | AD6: Process Sigma level | AE6: DPMU (ppm) | AG6: Class | AI6: Rolled-throughput Yield RTY
A7: Safety | B7: 1500 | C7: 1677 | D7: =IFERROR(C7/B7,"") -> 1.118 | E7: 192 | F7: =IFERROR(E7/C7,"") -> 0.11449016 | G7: 0.035 | H7: =IFERROR(F7-G7,"") -> 0.079490161 | J7: 15299 | K7: 15783 | L7: =+K7/J7 -> 1.0316361 | M7: 1253 | N7: =+M7/K7 -> 0.079389216 | O7: =1-N7 -> 0.92061078 | P7: =(1-N7)/L7 -> 0.89237942 | Q7: 0.035 | R7: =IFERROR((N7/Q7)-1,0) -> 1.2682633 | T7: 0.054050203 | U7: =IFERROR((N7/T7)-1,0) -> 0.46880514 | W7: 6 | X7: 1379 | Y7: =+X7/K7 -> 0.087372489 | Z7: =+X7/M7 -> 1.1005587 | AA7: =1-Y7 -> 0.91262751 | AB7: =+X7/(K7*W7) -> 0.014562082 | AC7: =+(X7/(K7*W7))*10^6 -> 14562.082 | AD7: =IF(K7=0,"",(IF((AC7/1000000)>0.933199,0,IF((AC7/1000000)>0.5,1.5-ABS(NORMSINV(AC7/1000000)),ABS(NORMSINV(AC7/1000000))+1.5)))) -> 3.6818018 | AE7: =+(M7/K7)*10^6 -> 79389.216 | AG7: =IF(AC7="","",IF(AC7>20000,"BRONZE",IF(AC7<=6000,"PLATINUM",IF(AC7>15000,"SILVER","GOLD")))) -> GOLD
A8: Leather | B8: 1510 | C8: 1480 | D8: =IFERROR(C8/B8,"") -> 0.98013245 | E8: 151 | F8: =IFERROR(E8/C8,"") -> 0.10202703 | G8: 0.075 | H8: =IFERROR(F8-G8,"") -> 0.027027027 | J8: 7929 | K8: 7919 | L8: =+K8/J8 -> 0.99873881 | M8: 811 | N8: =+M8/K8 -> 0.10241192 | O8: =1-N8 -> 0.89758808 | P8: =(1-N8)/L8 -> 0.89872154 | Q8: 0.075 | R8: =IFERROR((N8/Q8)-1,0) -> 0.36549228 | T8: 0.06107739 | U8: =IFERROR((N8/T8)-1,0) -> 0.67675666 | W8: 6 | X8: 985 | Y8: =+X8/K8 -> 0.12438439 | Z8: =+X8/M8 -> 1.2145499 | AA8: =1-Y8 -> 0.87561561 | AB8: =+X8/(K8*W8) -> 0.020730732 | AC8: =+(X8/(K8*W8))*10^6 -> 20730.732 | AD8: =IF(K8=0,"",(IF((AC8/1000000)>0.933199,0,IF((AC8/1000000)>0.5,1.5-ABS(NORMSINV(AC8/1000000)),ABS(NORMSINV(AC8/1000000))+1.5)))) -> 3.5388854 | AE8: =+(M8/K8)*10^6 -> 102411.92 | AG8: =IF(AC8="","",IF(AC8>20000,"BRONZE",IF(AC8<=6000,"PLATINUM",IF(AC8>15000,"SILVER","GOLD")))) -> BRONZE
A9: D|air | B9: 1382 | C9: 1350 | D9: =IFERROR(C9/B9,"") -> 0.97684515 | E9: 88 | F9: =IFERROR(E9/C9,"") -> 0.065185185 | G9: 0.005 | H9: =IFERROR(F9-G9,"") -> 0.060185185 | J9: 5952 | K9: 5908 | L9: =+K9/J9 -> 0.99260753 | M9: 130 | N9: =+M9/K9 -> 0.022004062 | O9: =1-N9 -> 0.97799594 | P9: =(1-N9)/L9 -> 0.98527959 | Q9: 0.005 | R9: =IFERROR((N9/Q9)-1,0) -> 3.4008125 | T9: 0.0013636612 | U9: =IFERROR((N9/T9)-1,0) -> 15.136019 | W9: 6 | X9: 130 | Y9: =+X9/K9 -> 0.022004062 | Z9: =+X9/M9 -> 1 | AA9: =1-Y9 -> 0.97799594 | AB9: =+X9/(K9*W9) -> 0.0036673437 | AC9: =+(X9/(K9*W9))*10^6 -> 3667.3437 | AD9: =IF(K9=0,"",IF(X9=0,6,IF((AC9/1000000)>0.933199,0,IF((AC9/1000000)>0.5,1.5-ABS(NORMSINV(AC9/1000000)),ABS(NORMSINV(AC9/1000000))+1.5)))) -> 4.1812538 | AE9: =+(M9/K9)*10^6 -> 22004.062 | AG9: =IF(AC9="","",IF(AC9>20000,"BRONZE",IF(AC9<=6000,"PLATINUM",IF(AC9>15000,"SILVER","GOLD")))) -> PLATINUM
A10: MEL-T | B10: =SUM(B7:B9) -> 4392 | C10: =SUM(C7:C9) -> 4507 | D10: =IFERROR(C10/B10,"") -> 1.026184 | E10: =SUM(E7:E9) -> 431 | F10: =IFERROR(E10/C10,"") -> 0.095629022 | G10: =AVERAGE(G7:G9) -> 0.038333333 | H10: =IFERROR(F10-G10,"") -> 0.057295688 | J10: =SUM(J7:J9) -> 29180 | K10: =SUM(K7:K9) -> 29610 | L10: =+K10/J10 -> 1.0147361 | M10: =SUM(M7:M9) -> 2194 | N10: =+M10/K10 -> 0.074096589 | O10: =1-N10 -> 0.92590341 | P10: =(1-N10)/L10 -> 0.91245733 | Q10: =AVERAGE(Q7:Q9) -> 0.038333333 | R10: =IFERROR((N10/Q10)-1,0) -> 0.9329545 | T10: 0.043450706 | U10: =IFERROR((N10/T10)-1,0) -> 0.7053023 | W10: 6 | X10: =SUM(X7:X9) -> 2494 | Y10: =+X10/K10 -> 0.084228301 | Z10: =+X10/M10 -> 1.1367366 | AA10: =1-Y10 -> 0.9157717 | AB10: =+X10/(K10*W10) -> 0.01403805 | AC10: =+(X10/(K10*W10))*10^6 -> 14038.05 | AD10: =IF(K10=0,"",(IF((AC10/1000000)>0.933199,0,IF((AC10/1000000)>0.5,1.5-ABS(NORMSINV(AC10/1000000)),ABS(NORMSINV(AC10/1000000))+1.5)))) -> 3.6962214 | AE10: =+(M10/K10)*10^6 -> 74096.589 | AG10: =IF(AC10="","",IF(AC10>20000,"BRONZE",IF(AC10<=6000,"PLATINUM",IF(AC10>15000,"SILVER","GOLD")))) -> GOLD | AI10: =PRODUCT(AA7:AA9) -> 0.78152721
A11: * The results of the D|air plant refer to the airbag sac (test sac 100%) ** Leather refer only to the Finished Goods
A13: BU | B13: 45838 | C13: 45869 | D13: 45900 | E13: 45930 | F13: 45961 | G13: 45991 | H13: 46022 | I13: 46053 | J13: 46081 | K13: 46112 | L13: 46142 | M13: 46173 | N13: 46203
A14: Safety | B14: 0.068409164 | C14: 0.049539171 | D14: 0.033482143 | E14: 0.048514251 | F14: 0.072122923 | G14: 0.043126685 | H14: 0.044018059 | I14: 0.054557777 | J14: 0.071646859 | K14: 0.10163468 | L14: 0.092005513 | M14: 0.059351816 | N14: 0.11449016
A15: Leather | B15: 0.06268307 | C15: 0.068376068 | D15: 0.078328982 | E15: 0.051051051 | F15: 0.070320579 | G15: 0.082182774 | H15: 0.12467306 | I15: 0.12712491 | J15: 0.089358245 | K15: 0.076028623 | L15: 0.08632041 | M15: 0.12773723 | N15: 0.10202703
A16: D|air | B16: 0.004587156 | C16: 0.0028208745 | D16: 0.0032051282 | E16: 0.0017006803 | F16: 0.0016411379 | G16: 0.0028801843 | H16: 0.00069979006 | I16: 0 | J16: 0 | K16: 0 | L16: 0 | M16: 0.067524116 | N16: 0.065185185
A17: MEL-T | B17: 0.049923664 | C17: 0.04919994 | D17: 0.037273173 | E17: 0.041293167 | F17: 0.053085887 | G17: 0.041831683 | H17: 0.049019608 | I17: 0.068181818 | J17: 0.063052445 | K17: 0.077436861 | L17: 0.06644805 | M17: 0.081045465 | N17: 0.095629022
A18: * The results of the BU D|air refer to the Airbag Sac
A21: Apparel - OQC Defective Rate Finished goods
A22: (Defective Units / Units Inspected) × 100
B24: MONTH JUN'26 | J24: YTD'26
A25: BU | B25: Qty prod | C25: Sample size | D25: Check Rate | E25: Defective units | F25: OQC Rej % | G25: TARGET | H25: +/- Vs trgt | J25: Qty prod | K25: Sample size | L25: Check Rate | M25: Defective units | N25: OQC Rej % | O25: % Yiled OQR | P25: % FPY | Q25: TARGET | R25: % Var. Vs trgt | T25: FY'25 | U25: % Var. Vs PY | W25: # Opportunities | X25: # Defects | Y25: DPU | Z25: DPR | AA25: Throughput Yield | AB25: DPO | AC25: DPMO | AD25: Process Sigma level | AE25: DPMU (ppm) | AG25: Class | AI25: Rolled-throughput Yield RTY
A26: Safety | B26: 1500 | C26: 433 | D26: =IFERROR(C26/B26,"") -> 0.28866667 | E26: 6 | F26: =IFERROR(E26/C26,"") -> 0.013856813 | G26: 0.015 | H26: =IFERROR(F26-G26,"") -> -0.0011431871 | J26: 15299 | K26: 4145 | L26: =+K26/J26 -> 0.27093274 | M26: 43 | N26: =+M26/K26 -> 0.010373945 | O26: =1-N26 -> 0.98962606 | Q26: 0.015 | R26: =IFERROR((N26/Q26)-1,0) -> -0.3084037 | T26: 0.01439158 | U26: =IFERROR((N26/T26)-1,0) -> -0.27916569 | W26: 7 | X26: 46 | Y26: =+X26/K26 -> 0.011097708 | Z26: =+X26/M26 -> 1.0697674 | AA26: =1-Y26 -> 0.98890229 | AB26: =+X26/(K26*W26) -> 0.0015853869 | AC26: =+(X26/(K26*W26))*10^6 -> 1585.3869 | AD26: =IF(AC26=0,6,(_xlfn.NORM.S.INV(1-(AC26/10^6)))+1.5) -> 4.4506779 | AE26: =+(M26/K26)*10^6 -> 10373.945 | AG26: =IF(AC26="","",IF(AC26>20000,"BRONZE",IF(AC26<=6000,"PLATINUM",IF(AC26>15000,"SILVER","GOLD")))) -> PLATINUM
A27: Leather | B27: 1510 | C27: 535 | D27: =IFERROR(C27/B27,"") -> 0.35430464 | E27: 2 | F27: =IFERROR(E27/C27,"") -> 0.0037383178 | G27: 0.015 | H27: =IFERROR(F27-G27,"") -> -0.011261682 | J27: 7929 | K27: 2703 | L27: =+K27/J27 -> 0.34090049 | M27: 14 | N27: =+M27/K27 -> 0.0051794303 | O27: =1-N27 -> 0.99482057 | Q27: 0.015 | R27: =IFERROR((N27/Q27)-1,0) -> -0.65470465 | T27: 0.010797016 | U27: =IFERROR((N27/T27)-1,0) -> -0.52029059 | W27: 7 | X27: 15 | Y27: =+X27/K27 -> 0.0055493896 | Z27: =+X27/M27 -> 1.0714286 | AA27: =1-Y27 -> 0.99445061 | AB27: =+X27/(K27*W27) -> 0.00079276994 | AC27: =+(X27/(K27*W27))*10^6 -> 792.76994 | AD27: =IF(AC27=0,6,(_xlfn.NORM.S.INV(1-(AC27/10^6)))+1.5) -> 4.6585539 | AE27: =+(M27/K27)*10^6 -> 5179.4303 | AG27: =IF(AC27="","",IF(AC27>20000,"BRONZE",IF(AC27<=6000,"PLATINUM",IF(AC27>15000,"SILVER","GOLD")))) -> PLATINUM
A28: D|air | B28: 1019 | C28: 322 | D28: =IFERROR(C28/B28,"") -> 0.31599607 | E28: 2 | F28: =IFERROR(E28/C28,"") -> 0.0062111801 | G28: 0.005 | H28: =IFERROR(F28-G28,"") -> 0.0012111801 | J28: 6583 | K28: 1560 | L28: =+K28/J28 -> 0.23697402 | M28: 8 | N28: =+M28/K28 -> 0.0051282051 | O28: =1-N28 -> 0.99487179 | Q28: 0.005 | R28: =IFERROR((N28/Q28)-1,0) -> 0.025641026 | T28: 0.0064613397 | U28: =IFERROR((N28/T28)-1,0) -> -0.20632479 | W28: 7 | X28: 8 | Y28: =+X28/K28 -> 0.0051282051 | Z28: =+X28/M28 -> 1 | AA28: =1-Y28 -> 0.99487179 | AB28: =+X28/(K28*W28) -> 0.00073260073 | AC28: =+(X28/(K28*W28))*10^6 -> 732.60073 | AD28: =IF(AC28=0,6,(_xlfn.NORM.S.INV(1-(AC28/10^6)))+1.5) -> 4.6814889 | AE28: =+(M28/K28)*10^6 -> 5128.2051 | AG28: =IF(AC28="","",IF(AC28>20000,"BRONZE",IF(AC28<=6000,"PLATINUM",IF(AC28>15000,"SILVER","GOLD")))) -> PLATINUM
A29: MEL-T | B29: =SUM(B26:B28) -> 4029 | C29: =SUM(C26:C28) -> 1290 | D29: =IFERROR(C29/B29,"") -> 0.3201787 | E29: =SUM(E26:E28) -> 10 | F29: =IFERROR(E29/C29,"") -> 0.007751938 | G29: =AVERAGE(G26:G28) -> 0.011666667 | H29: =IFERROR(F29-G29,"") -> -0.0039147287 | J29: =SUM(J26:J28) -> 29811 | K29: =SUM(K26:K28) -> 8408 | L29: =+K29/J29 -> 0.28204354 | M29: =SUM(M26:M28) -> 65 | N29: =+M29/K29 -> 0.0077307326 | O29: =1-N29 -> 0.99226927 | Q29: =AVERAGE(Q26:Q28) -> 0.011666667 | R29: =IFERROR((N29/Q29)-1,0) -> -0.33736577 | T29: 0.01149727 | U29: =IFERROR((N29/T29)-1,0) -> -0.32760276 | W29: 7 | X29: =SUM(X26:X28) -> 69 | Y29: =+X29/K29 -> 0.00820647 | Z29: =+X29/M29 -> 1.0615385 | AA29: =1-Y29 -> 0.99179353 | AB29: =+X29/(K29*W29) -> 0.0011723529 | AC29: =+(X29/(K29*W29))*10^6 -> 1172.3529 | AD29: =IF(AC29=0,6,(_xlfn.NORM.S.INV(1-(AC29/10^6)))+1.5) -> 4.5426941 | AE29: =+(M29/K29)*10^6 -> 7730.7326 | AG29: =IF(AC29="","",IF(AC29>20000,"BRONZE",IF(AC29<=6000,"PLATINUM",IF(AC29>15000,"SILVER","GOLD")))) -> PLATINUM | AI29: =PRODUCT(AA26:AA28) -> 0.97837134
A30: * The results of the BU refer to the Finished Goods
A32: BU | B32: 45838 | C32: 45869 | D32: 45900 | E32: 45930 | F32: 45961 | G32: 45991 | H32: 46022 | I32: 46053 | J32: 46081 | K32: 46112 | L32: 46142 | M32: 46173 | N32: 46203
A33: Safety | B33: 0.0054347826 | C33: 0 | D33: 0.0086956522 | E33: 0.012617221 | F33: 0.024288107 | G33: 0.026275116 | H33: 0.0021691974 | I33: 0.017567568 | J33: 0.007585335 | K33: 0.010479042 | L33: 0.012642225 | M33: 0.0013850416 | N33: 0.013856813
A34: Leather | B34: 0.0091116173 | C34: 0.0067226891 | D34: 0 | E34: 0.013565891 | F34: 0.0014245014 | G34: 0.016393443 | H34: 0.022727273 | I34: 0 | J34: 0.017632242 | K34: 0.0029069767 | L34: 0.002016129 | M34: 0.0065075922 | N34: 0.0037383178
A35: D|air | B35: 0.01320132 | C35: 0 | D35: 0 | E35: 0 | F35: 0.008291874 | G35: 0 | H35: 0 | I35: 0.0076923077 | J35: 0 | K35: 0 | L35: 0.012820513 | M35: 0.0037313433 | N35: 0.0062111801
A36: MEL-T | B36: 0.0081190798 | C36: 0.0021609941 | D36: 0.004601227 | E36: 0.010835641 | F36: 0.014005602 | G36: 0.020466445 | H36: 0.0072683222 | I36: 0.010204082 | J36: 0.0090277778 | K36: 0.0064724919 | L36: 0.0092044707 | M36: 0.0034458994 | N36: 0.007751938
A54: Further definitions:
A55: Defects and units are fairly straightforward but some folks struggle with the number of opportunities. The number of opportunities is based on how you choose to count defects. Here are some examples:
A56: One opportunity: an item is either wrong or right, good or bad.
A57: Two opportunities: A package could have the wrong product or the wrong # products in it.
A58: Example of three opportunities: a shirt you order could be the wrong: size, style or color.
A60: Six Sigma Table: | D60: 1 | E60: 690000
D61: 2 | E61: 308000
D62: 3 | E62: 66800
D63: 4 | E63: 6210
D64: 5 | E64: 320
...

Sheet Ph_QC
A1: Productivity (p/h) - FQC
A2: (Finished goods output / Total worked hours)
A3: BU | C3: 45688 | D3: 45716 | E3: 45747 | F3: 45777 | G3: 45808 | H3: 45838 | I3: 45869 | J3: 45900 | K3: 45930 | L3: 45961 | M3: 45991 | N3: 46022 | O3: 46053 | P3: 46081 | Q3: 46112 | R3: 46142 | S3: 46173 | T3: 46203 | U3: YTD | V3: TARGET | W3: %Var. Vs trgt | X3: MoM% | Y3: PYTD | Z3: YoY %
A4: BU02 - Safety | B4: QC_Pcs | C4: 4377 | D4: 3694 | E4: 3161 | F4: 3199 | G4: 3454 | H4: 2969 | I4: 4374 | J4: 1312 | K4: 1683 | L4: 5771 | M4: 4927 | N4: 3646 | O4: 2951 | P4: 2686 | Q4: 2775 | R4: 2893 | S4: 2500 | T4: 1561 | U4: =SUM(O4:T4) -> 15366 | X4: =IFERROR(T4/S4-1,100%) -> -0.3756 | Y4: =SUM(C4:H4) -> 20854 | Z4: =+U4/Y4-1 -> -0.26316294
A5: BU02 - Safety | B5: Worked Hrs | C5: 388 | D5: 393 | E5: 291 | F5: 259 | G5: 323.5 | H5: 356 | I5: 273 | J5: 74.5 | K5: 346 | L5: 504.5 | M5: 428.5 | N5: 351 | O5: 290.5 | P5: 333.5 | Q5: 442.5 | R5: 508.5 | S5: 325 | T5: 360 | U5: =SUM(O5:T5) -> 2260 | X5: =IFERROR(T5/S5-1,100%) -> 0.10769231 | Y5: =SUM(C5:H5) -> 2010.5 | Z5: =+U5/Y5-1 -> 0.12409848
A6: BU02 - Safety | B6: Productivity_QC_Ph | C6: 11.280928 | D6: 9.3994911 | E6: 10.862543 | F6: 12.351351 | G6: 10.676971 | H6: 8.3398876 | I6: 16.021978 | J6: 17.610738 | K6: 4.8641618 | L6: 11.439049 | M6: 11.49825 | N6: 10.387464 | O6: 10.158348 | P6: 8.053973 | Q6: 6.2711864 | R6: 5.6892822 | S6: 7.6923077 | T6: 4.3361111 | U6: =+U4/U5 -> 6.799115 | V6: 8.1872465 | W6: =+U6/V6-1 -> -0.16954802 | X6: =IFERROR(T6/S6-1,100%) -> -0.43630556 | Y6: =+Y4/Y5 -> 10.372544 | Z6: =+U6/Y6-1 -> -0.34450845
A8: BU03 - Leather | B8: QC_Pcs | C8: 2304 | D8: 1643 | E8: 1500 | F8: 1283 | G8: 1524 | H8: 1766 | I8: 1679 | J8: 367 | K8: 960 | L8: 2837 | M8: 1490 | N8: 1073 | O8: 1358 | P8: 1221 | Q8: 1127 | R8: 1329 | S8: 1435 | T8: 1511 | U8: =SUM(O8:T8) -> 7981 | X8: =IFERROR(T8/S8-1,100%) -> 0.052961672 | Y8: =SUM(C8:H8) -> 10020 | Z8: =+U8/Y8-1 -> -0.20349301
A9: BU03 - Leather | B9: Worked Hrs | C9: 419.5 | D9: 459.5 | E9: 375 | F9: 346.5 | G9: 408 | H9: 432.5 | I9: 450.5 | J9: 75.5 | K9: 361.5 | L9: 433 | M9: 355.5 | N9: 407 | O9: 367 | P9: 386 | Q9: 354.5 | R9: 384 | S9: 444 | T9: 504.5 | U9: =SUM(O9:T9) -> 2440 | X9: =IFERROR(T9/S9-1,100%) -> 0.13626126 | Y9: =SUM(C9:H9) -> 2441 | Z9: =+U9/Y9-1 -> -0.00040966817
A10: BU03 - Leather | B10: Productivity_QC_Ph | C10: 5.4922527 | D10: 3.5756257 | E10: 4 | F10: 3.7027417 | G10: 3.7352941 | H10: 4.083237 | I10: 3.72697 | J10: 4.8609272 | K10: 2.6556017 | L10: 6.551963 | M10: 4.1912799 | N10: 2.6363636 | O10: 3.7002725 | P10: 3.1632124 | Q10: 3.1791255 | R10: 3.4609375 | S10: 3.231982 | T10: 2.9950446 | U10: =+U8/U9 -> 3.2709016 | V10: 1.97 | W10: =+U10/V10-1 -> 0.66035616 | X10: =IFERROR(T10/S10-1,100%) -> -0.073310243 | Y10: =+Y8/Y9 -> 4.1048751 | Z10: =+U10/Y10-1 -> -0.20316658
A12: BU04 - D|air | B12: QC_Pcs | Y12: =SUM(C12:H12) -> 0
A13: BU04 - D|air | B13: Worked Hrs | Y13: =SUM(C13:H13) -> 0
A14: BU04 - D|air | B14: Productivity_QC_Ph
A16: QC_Pcs totale | C16: 6681 | D16: 5337 | E16: 4661 | F16: 4482 | G16: 4978 | H16: 4735 | I16: 6053 | J16: 1679 | K16: 2643 | L16: 8608 | M16: 6417 | N16: 4719 | O16: 4309 | P16: 3907 | Q16: 3902 | R16: 4222 | S16: 3935 | T16: 3072 | U16: =SUM(O16:T16) -> 23347 | X16: =IFERROR(T16/S16-1,100%) -> -0.21931385 | Y16: =SUM(C16:H16) -> 30874 | Z16: =+U16/Y16-1 -> -0.24379737
A17: Worked Hrs totale | C17: 807.5 | D17: 852.5 | E17: 666 | F17: 605.5 | G17: 731.5 | H17: 788.5 | I17: 723.5 | J17: 150 | K17: 707.5 | L17: 937.5 | M17: 784 | N17: 758 | O17: 657.5 | P17: 719.5 | Q17: 797 | R17: 892.5 | S17: 769 | T17: 864.5 | U17: =SUM(O17:T17) -> 4700 | X17: =IFERROR(T17/S17-1,100%) -> 0.12418726 | Y17: =SUM(C17:H17) -> 4451.5 | Z17: =+U17/Y17-1 -> 0.05582388
A18: Productivity_QC_Ph totale | C18: 8.2736842 | D18: 6.2604106 | E18: 6.9984985 | F18: 7.402147 | G18: 6.8051948 | H18: 6.0050729 | I18: 8.3662751 | J18: 11.193333 | K18: 3.735689 | L18: 9.1818667 | M18: 8.184949 | N18: 6.2255937 | O18: 6.5536122 | P18: 5.4301598 | Q18: 4.8958595 | R18: 4.7305322 | S18: 5.1170351 | T18: 3.5534991 | U18: =+U16/U17 -> 4.9674468 | V18: 6.56 | W18: =+U18/V18-1 -> -0.24276725 | X18: =IFERROR(T18/S18-1,100%) -> -0.30555506 | Y18: =+Y16/Y17 -> 6.9356397 | Z18: =+U18/Y18-1 -> -0.28377957
A19: * Non incluso IPQC-FPLS
A21: Throughtput (p/h) - FQC
A22: (Finished goods output / 1.0 FTE worked hours)
A23: BU_CDC | C23: 45688 | D23: 45716 | E23: 45747 | F23: 45777 | G23: 45808 | H23: 45838 | I23: 45869 | J23: 45900 | K23: 45930 | L23: 45961 | M23: 45991 | N23: 46022 | O23: 46053 | P23: 46081 | Q23: 46112 | R23: 46142 | S23: 46173 | T23: 46203 | U23: YTD | V23: TARGET | W23: %Var. Vs trgt | X23: MoM% | Y23: PYTD | Z23: YoY %
A24: BU02 - Safety | B24: QC_Pcs | C24: 4377 | D24: 3694 | E24: 3161 | F24: 3199 | G24: 3454 | H24: 2969 | I24: 4374 | J24: 1312 | K24: 1683 | L24: 5771 | M24: 4927 | N24: 3646 | O24: 2951 | P24: 2686 | Q24: 2775 | R24: 2893 | S24: 2500 | T24: 1561 | U24: =SUM(O24:T24) -> 15366 | X24: =IFERROR(T24/S24-1,100%) -> -0.3756 | Y24: =SUM(C24:H24) -> 20854 | Z24: =+U24/Y24-1 -> -0.26316294
A25: BU02 - Safety | B25: Run_hrs_YTD | C25: 202 | D25: 185 | E25: 133 | F25: 136 | G25: 170 | H25: 160.5 | I25: 194.5 | J25: 34 | K25: 183 | L25: 210.5 | M25: 185 | N25: 187 | O25: 192.5 | P25: 178 | Q25: 164.5 | R25: 202 | S25: 169 | T25: 205.5 | U25: =SUM(O25:T25) -> 1111.5 | X25: =IFERROR(T25/S25-1,100%) -> 0.21597633 | Y25: =SUM(C25:H25) -> 986.5 | Z25: =+U25/Y25-1 -> 0.12671059
A26: BU02 - Safety | B26: Throughput (ph)_QC | C26: 21.668317 | D26: 19.967568 | E26: 23.766917 | F26: 23.522059 | G26: 20.317647 | H26: 18.498442 | I26: 22.488432 | J26: 38.588235 | K26: 9.1967213 | L26: 27.415677 | M26: 26.632432 | N26: 19.497326 | O26: 15.32987 | P26: 15.089888 | Q26: 16.869301 | R26: 14.321782 | S26: 14.792899 | T26: 7.5961071 | U26: =+U24/U25 -> 13.824561 | V26: 40.936233 | W26: =+U26/V26-1 -> -0.66229033 | X26: =IFERROR(T26/S26-1,100%) -> -0.48650316 | Y26: =+Y24/Y25 -> 21.139382 | Z26: =+U26/Y26-1 -> -0.34602811
A28: BU03 - Leather | B28: QC_Pcs | C28: 2304 | D28: 1643 | E28: 1500 | F28: 1283 | G28: 1524 | H28: 1766 | I28: 1679 | J28: 367 | K28: 960 | L28: 2837 | M28: 1490 | N28: 1073 | O28: 1358 | P28: 1221 | Q28: 1127 | R28: 1329 | S28: 1434 | T28: 1511 | U28: =SUM(O28:T28) -> 7980 | X28: =IFERROR(T28/S28-1,100%) -> 0.053695955 | Y28: =SUM(C28:H28) -> 10020 | Z28: =+U28/Y28-1 -> -0.20359281
A29: BU03 - Leather | B29: Run_hrs_YTD | C29: 202 | D29: 185 | E29: 133 | F29: 136 | G29: 170 | H29: 160.5 | I29: 194.5 | J29: 34 | K29: 183 | L29: 210.5 | M29: 185 | N29: 187 | O29: 192.5 | P29: 178 | Q29: 164.5 | R29: 202 | S29: 169 | T29: 205.5 | U29: =SUM(O29:T29) -> 1111.5 | X29: =IFERROR(T29/S29-1,100%) -> 0.21597633 | Y29: =SUM(C29:H29) -> 986.5 | Z29: =+U29/Y29-1 -> 0.12671059
A30: BU03 - Leather | B30: Throughput (ph)_QC | C30: 11.405941 | D30: 8.8810811 | E30: 11.278195 | F30: 9.4338235 | G30: 8.9647059 | H30: 11.003115 | I30: 8.6323907 | J30: 10.794118 | K30: 5.2459016 | L30: 13.477435 | M30: 8.0540541 | N30: 5.7379679 | O30: 7.0545455 | P30: 6.8595506 | Q30: 6.8510638 | R30: 6.5792079 | S30: 8.4852071 | T30: 7.3527981 | U30: =+U28/U29 -> 7.1794872 | V30: 9.83 | W30: =+U30/V30-1 -> -0.26963508 | X30: =IFERROR(T30/S30-1,100%) -> -0.13345685 | Y30: =+Y28/Y29 -> 10.157121 | Z30: =+U30/Y30-1 -> -0.29315728
A32: BU04 - D|air | B32: QC_Pcs | Y32: =SUM(C32:H32) -> 0
A33: BU04 - D|air | B33: Run_hrs_YTD | C33: 202 | D33: 185 | E33: 133 | F33: 136 | G33: 170 | H33: 160.5 | I33: 194.5 | J33: 34 | K33: 183 | L33: 210.5 | M33: 185 | N33: 187 | O33: 192.5 | P33: 178 | Q33: 164.5 | R33: 202 | S33: 169 | T33: 205.5 | U33: =SUM(O33:T33) -> 1111.5 | Y33: =SUM(C33:H33) -> 986.5
A34: BU04 - D|air | B34: Throughput (ph)_QC | Y34: =+Y32/Y33 -> 0
A36: QC_Pcs totale | C36: 6681 | D36: 5337 | E36: 4661 | F36: 4482 | G36: 4978 | H36: 4735 | I36: 6053 | J36: 1679 | K36: 2643 | L36: 8608 | M36: 6417 | N36: 4719 | O36: 4309 | P36: 3907 | Q36: 3902 | R36: 4222 | S36: 3934 | T36: 3072 | U36: =SUM(O36:T36) -> 23346 | X36: =IFERROR(T36/S36-1,100%) -> -0.2191154 | Y36: =SUM(C36:H36) -> 30874 | Z36: =+U36/Y36-1 -> -0.24382976
A37: Run_hrs_YTD totale | C37: 202 | D37: 185 | E37: 133 | F37: 136 | G37: 170 | H37: 160.5 | I37: 194.5 | J37: 34 | K37: 183 | L37: 210.5 | M37: 185 | N37: 187 | O37: 192.5 | P37: 178 | Q37: 164.5 | R37: 202 | S37: 169 | T37: 205.5 | U37: =SUM(O37:T37) -> 1111.5 | X37: =IFERROR(T37/S37-1,100%) -> 0.21597633 | Y37: =SUM(C37:H37) -> 986.5 | Z37: =+U37/Y37-1 -> 0.12671059
A38: Throughput (ph)_QC totale | C38: 33.074257 | D38: 28.848649 | E38: 35.045113 | F38: 32.955882 | G38: 29.282353 | H38: 29.501558 | I38: 31.120823 | J38: 49.382353 | K38: 14.442623 | L38: 40.893112 | M38: 34.686486 | N38: 25.235294 | O38: 22.384416 | P38: 21.949438 | Q38: 23.720365 | R38: 20.90099 | S38: 23.278107 | T38: 14.948905 | U38: =+U36/U37 -> 21.004049 | V38: 65.58 | W38: =+U38/V38-1 -> -0.67971869 | X38: =IFERROR(T38/S38-1,100%) -> -0.35781267 | Y38: =+Y36/Y37 -> 31.296503 | Z38: =+U38/Y38-1 -> -0.32886915

Sheet Efficiency
A1: Productivity & Efficiency
A2: Operational Efficiency % (O-Eff%)
A3: (Standard minutes produced × Standard cycle time) / Total worked minutes × 100
A4: SAFETY | B4: 45688 | C4: 45716 | D4: 45747 | E4: 45777 | F4: 45808 | G4: 45838 | H4: 45869 | I4: 45900 | J4: 45930 | K4: 45961 | L4: 45991 | M4: 46022 | N4: 46053 | O4: 46081 | P4: 46112 | Q4: 46142 | R4: 46173 | S4: 46203 | T4: YTD | U4: TARGET | V4: % Var. vs trgt | W4: MoM % | X4: PYTD | Y4: YoY% | Z4: WIP FG | AA4: coda 2025 su 2026
A5: Production Volume FG | B5: 4523 | C5: 3850 | D5: 2740 | E5: 3280 | F5: 3583 | G5: 2928 | H5: 4382 | I5: 1140 | J5: 3357 | K5: 3617 | L5: 4784 | M5: 3331 | N5: 3246 | O5: 2503 | P5: 2749 | Q5: 2769 | R5: 2532 | S5: 1500 | T5: =SUM(N5:S5) -> 15299 | W5: =IFERROR(S5/R5-1,100%) -> -0.40758294 | X5: =SUM(B5:G5) -> 20904 | Y5: =+T5/X5-1 -> -0.2681305 | Z5: =+T5+AA5-Delivery!U40 -> 18 | AA5: 1537
A6: Std minutes produced | B6: 202146.49 | C6: 170449.61 | D6: 136977.9 | E6: 112796.4 | F6: 153489.39 | G6: 133601.25 | H6: 171640.58 | I6: 25459.24 | J6: 142370.34 | K6: 153598.73 | L6: 163253.58 | M6: 155414.94 | N6: 131914.28 | O6: 115658.17 | P6: 118011.03 | Q6: 137511.03 | R6: 104725.79 | S6: 100927.74 | T6: =SUM(N6:S6) -> 708748.04 | W6: =IFERROR(S6/R6-1,100%) -> -0.036266616 | X6: =SUM(B6:G6) -> 909461.04 | Y6: =+T6/X6-1 -> -0.22069445
A7: Worked minutes | B7: 304050 | C7: 276330 | D7: 219150 | E7: 190080 | F7: 219780 | G7: 200400 | H7: 239400 | I7: 43050 | J7: 212970 | K7: 248370 | L7: 217110 | M7: 208800 | N7: 190860 | O7: 176870 | P7: 180120 | Q7: 191220 | R7: 151080 | S7: 178980 | T7: =SUM(N7:S7) -> 1069130 | W7: =IFERROR(S7/R7-1,100%) -> 0.18467037 | X7: =SUM(B7:G7) -> 1409790 | Y7: =+T7/X7-1 -> -0.24163883
A8: Efficiency (mth) | B8: =IFERROR(B6/B7,"") -> 0.66484621 | C8: =IFERROR(C6/C7,"") -> 0.61683353 | D8: =IFERROR(D6/D7,"") -> 0.62504175 | E8: =IFERROR(E6/E7,"") -> 0.5934154 | F8: =IFERROR(F6/F7,"") -> 0.69837742 | G8: =IFERROR(G6/G7,"") -> 0.6666729 | H8: =IFERROR(H6/H7,"") -> 0.71696149 | I8: =IFERROR(I6/I7,"") -> 0.59138769 | ... S8: =IFERROR(S6/S7,"") -> 0.56390513 | W8: =IFERROR(S8/R8-1,100%) -> -0.18649659
A9: Efficiency (ytd) | B9: =SUM($B6:B6)/SUM($B7:B7) -> 0.66484621 | C9: =SUM($B6:C6)/SUM($B7:C7) -> 0.64198646 | D9: =SUM($B6:D6)/SUM($B7:D7) -> 0.63734194 | E9: =SUM($B6:E6)/SUM($B7:E7) -> 0.62890472 | F9: =SUM($B6:F6)/SUM($B7:F7) -> 0.64152985 | G9: =SUM($B6:G6)/SUM($B7:G7) -> 0.64510391 | H9: =SUM($B6:H6)/SUM($B7:H7) -> 0.65553491 | I9: =SUM($B6:I6)/SUM($B7:I7) -> 0.65390303 | ... M9: =SUM($B6:M6)/SUM($B7:M7) -> 0.66726308 | N9: =SUM(N6:$N6)/SUM(N7:$N7) -> 0.69115729 | O9: =SUM($N6:O6)/SUM($N7:O7) -> 0.67324517 | P9: =SUM($N6:P6)/SUM($N7:P7) -> 0.66730579 | Q9: =SUM($N6:Q6)/SUM($N7:Q7) -> 0.68071293 | R9: =SUM($N6:R6)/SUM($N7:R7) -> 0.68282907 | S9: =SUM($N6:S6)/SUM($N7:S7) -> 0.66292035 | T9: =+T6/T7 -> 0.66292035 | U9: 0.79 | V9: =T9/U9-1 -> -0.16086031 | W9: =IFERROR(S9/R9-1,100%) -> -0.029156224 | X9: =+X6/X7 -> 0.64510391 | Y9: =+T9/X9-1 -> 0.027617944
A10: Productivity (p/h) | B10: =IFERROR(B5/(B7/60),0) -> 0.89255057 | C10: =IFERROR(C5/(C7/60),0) -> 0.83595701 | D10: =IFERROR(D5/(D7/60),0) -> 0.75017112 | E10: =IFERROR(E5/(E7/60),0) -> 1.0353535 | F10: =IFERROR(F5/(F7/60),0) -> 0.97815998 | G10: =IFERROR(G5/(G7/60),0) -> 0.87664671 | H10: =IFERROR(H5/(H7/60),0) -> 1.0982456 | I10: =IFERROR(I5/(I7/60),0) -> 1.5888502 | ... T10: =IFERROR(T5/(T7/60),0) -> 0.85858595 | U10: 1.05 | V10: =T10/U10-1 -> -0.18229909 | W10: =IFERROR(S10/R10-1,100%) -> -0.49993089 | X10: =+X5/(X7/60) -> 0.88966442 | Y10: =+T10/X10-1 -> -0.034932795
A12: LEATHER | B12: 45688 | C12: 45716 | D12: 45747 | E12: 45777 | F12: 45808 | G12: 45838 | H12: 45869 | I12: 45900 | J12: 45930 | K12: 45961 | L12: 45991 | M12: 46022 | N12: 46053 | O12: 46081 | P12: 46112 | Q12: 46142 | R12: 46173 | S12: 46203 | T12: YTD | U12: TARGET | V12: % Var. vs trgt | W12: MoM % | X12: PYTD | Y12: YoY% | Z12: WIP FG | AA12: coda 2025 su 2026
A13: Production Volume FG | B13: 2331 | C13: 1625 | D13: 1493 | E13: 1285 | F13: 1532 | G13: 1764 | H13: 1715 | I13: 339 | J13: 1901 | K13: 1913 | L13: 1455 | M13: 1098 | N13: 1375 | O13: 1193 | P13: 1131 | Q13: 1273 | R13: 1380 | S13: 1510 | T13: =SUM(N13:S13) -> 7862 | W13: =IFERROR(S13/R13-1,100%) -> 0.094202899 | X13: =SUM(B13:G13) -> 10030 | Y13: =+T13/X13-1 -> -0.21615155 | Z13: =+T13+AA13-Delivery!U41 -> 141 | AA13: 605
A14: Std minutes produced | B14: 769873.22 | C14: 630240.11 | D14: 484938.8 | E14: 440865.74 | F14: 558572.5 | G14: 589885.72 | H14: 667067.34 | I14: 136692.47 | J14: 631411.39 | K14: 690790.96 | L14: 497397.76 | M14: 433900 | N14: 435609.9 | O14: 432189.38 | P14: 393442.09 | Q14: 515577.83 | R14: 479471.31 | S14: 580505.27 | T14: =SUM(N14:S14) -> 2836795.8 | W14: =IFERROR(S14/R14-1,100%) -> 0.21071951 | X14: =SUM(B14:G14) -> 3474376.1 | Y14: =+T14/X14-1 -> -0.1835093
A15: Worked minutes | B15: 955230 | C15: 853590 | D15: 604860 | E15: 583140 | F15: 744690 | G15: 726420 | H15: 910500 | I15: 169920 | J15: 841230 | K15: 950010 | L15: 805470 | M15: 776310 | N15: 758100 | O15: 721180 | P15: 602550 | Q15: 820350 | R15: 709140 | S15: 869880 | T15: =SUM(N15:S15) -> 4481200 | W15: =IFERROR(S15/R15-1,100%) -> 0.22666892 | X15: =SUM(B15:G15) -> 4467930 | Y15: =+T15/X15-1 -> 0.0029700555
