Workbook

Sheet État
B1: ÉTAT D'EXPLOITATION QUALIPRO — TAUX D'UTILISATION PAR LES RESPONSABLES
B2: ="Indicateur = jours ouvrés avec au moins 1 accès ÷ jours ouvrés attendus (par responsable, effectif du mois). Cible direction : 1 accès par jour ouvré · Objectif atteint ≥ "&ROUND(Paramètres!B5*100,0)&" % · Alerte ≥ "&ROUND(Paramètres!B6*100,0)&" %" -> Indicateur = jours ouvrés avec au moins 1 accès ÷ jours ouvrés attendus (par responsable, effectif du mois). Cible direction : 1 accès par jour ouvré · Objectif atteint ≥ 70 % · Alerte ≥ 40 %
B4: Mois : | C4: Septembre 2026 | E4: ◄ choisir le mois dans la liste
B6: TAUX D'UTILISATION GLOBAL | D6: STATUT | E6: JOURS CONSULTÉS / ATTENDUS | G6: RESPONSABLES ACTIFS / SANS ACCÈS | I6: VARIATION VS MOIS PRÉC.
B7: =INDEX(Calcul!$AC$35:$AN$35,Calcul!$C$48) -> 0.20606061 | D7: =IF(B7="","",IF(B7>=Paramètres!B5,"OBJECTIF ATTEINT",IF(B7>=Paramètres!B6,"ALERTE","CRITIQUE"))) -> CRITIQUE | E7: =INDEX(Calcul!$P$35:$AA$35,Calcul!$C$48)&" / "&INDEX(Calcul!$C$35:$N$35,Calcul!$C$48) -> 68 / 330 | G7: =INDEX(Calcul!$C$36:$N$36,Calcul!$C$48)&" / "&INDEX(Calcul!$C$37:$N$37,Calcul!$C$48) -> 15 / 3 | I7: =IF(OR(Calcul!$C$48=1,B7=""),"n/a",IF(ISNUMBER(INDEX(Calcul!$AC$35:$AN$35,MAX(1,Calcul!$C$48-1))),IF(Calcul!$C$48=1,"n/a",B7-INDEX(Calcul!$AC$35:$AN$35,Calcul!$C$48-1)),"n/a")) -> -0.010606061
B9: ="Répartition : "&INDEX(Calcul!$C$38:$N$38,Calcul!$C$48)&" modèle(s) · "&INDEX(Calcul!$C$39:$N$39,Calcul!$C$48)&" régulier(s) · "&INDEX(Calcul!$C$40:$N$40,Calcul!$C$48)&" critique(s) | Taux ajusté au rôle (moyenne des responsables) : "&IF(INDEX(Calcul!$AP$35:$BA$35,Calcul!$C$48)="","n/a",ROUND(INDEX(Calcul!$AP$35:$BA$35,Calcul!$C$48)*100,1)&" %")&" | Jours ouvrés du mois : "&INDEX(Calcul!$C$43:$N$43,Calcul!$C$48) -> Répartition : 0 modèle(s) · 2 régulier(s) · 13 critique(s) | Taux ajusté au rôle (moyenne des responsables) : 20,6 % | Jours ouvrés du mois : 22
B11: ="Lecture : en "&C4&", "&ROUND(B7*100,1)&" % des jours ouvrés attendus ont donné lieu à au moins un accès ("&INDEX(Calcul!$P$35:$AA$35,Calcul!$C$48)&" jours consultés sur "&INDEX(Calcul!$C$35:$N$35,Calcul!$C$48)&")."&IF(B7>=Paramètres!B5," Objectif atteint.",IF(B7>=Paramètres!B6," Niveau d'alerte : l'objectif de "&ROUND(Paramètres!B5*100,0)&" % n'est pas atteint."," Niveau critique, très en dessous de l'objectif de "&ROUND(Paramètres!B5*100,0)&" %."))&IF(ISNUMBER(I7)," Évolution : "&IF(I7>=0,"+","")&ROUND(I7*100,1)&" pts vs mois précédent.","")&IF(INDEX(Calcul!$C$37:$N$37,Calcul!$C$48)>0," "&INDEX(Calcul!$C$37:$N$37,Calcul!$C$48)&" responsable(s) sans aucun accès ce mois-ci.","") -> Lecture : en Septembre 2026, 20,6 % des jours ouvrés attendus ont donné lieu à au moins un accès (68 jours consultés sur 330). Niveau critique, très en dessous de l'objectif de 70 %. Évolution : -1,1 pts vs mois précédent. 3 responsable(s) sans aucun accès ce mois-ci.
B14: Rang | C14: Responsable | D14: Fonction / rôle | E14: Jours attendus | F14: Jours consultés | G14: Taux | H14: Statut | I14: Δ vs mois préc. (pts) | J14: Taux ajusté au rôle
B15: =IF($K15="","",1) -> 1 | C15: =IF($K15="","",INDEX(Calcul!$A$5:$A$34,$K15)) -> Ahlem Moussa | D15: =IF($K15="","",IF(INDEX(Paramètres!$B$11:$B$40,$K15)="","—",INDEX(Paramètres!$B$11:$B$40,$K15))) -> Quality Inspector | E15: =IF($K15="","",INDEX(Calcul!$C$5:$N$34,$K15,Calcul!$C$48)) -> 22 | F15: =IF($K15="","",INDEX(Calcul!$P$5:$AA$34,$K15,Calcul!$C$48)) -> 13 | G15: =IF($K15="","",IF(E15=0,"",F15/E15)) -> 0.59090909 | H15: =IF(G15="","",IF(G15>=Paramètres!$B$5,"● Modèle",IF(G15>=Paramètres!$B$6,"● Régulier","● Critique"))) -> ● Régulier | I15: =IF(OR($K15="",Calcul!$C$48=1),"",IF(ISNUMBER(INDEX(Calcul!$AC$5:$AN$34,$K15,MAX(1,Calcul!$C$48-1))),G15-INDEX(Calcul!$AC$5:$AN$34,$K15,MAX(1,Calcul!$C$48-1)),"")) -> 0.21590909 | J15: =IF($K15="","",INDEX(Calcul!$AP$5:$BA$34,$K15,Calcul!$C$48)) -> 0.59090909 | K15: =IFERROR(MATCH(1,Calcul!$BF$5:$BF$34,0),"") -> 1
B16: =IF($K16="","",2) -> 2 | C16: =IF($K16="","",INDEX(Calcul!$A$5:$A$34,$K16)) -> Ines Farhat | D16: =IF($K16="","",IF(INDEX(Paramètres!$B$11:$B$40,$K16)="","—",INDEX(Paramètres!$B$11:$B$40,$K16))) -> Quality Control & PACK Supervisor | E16: =IF($K16="","",INDEX(Calcul!$C$5:$N$34,$K16,Calcul!$C$48)) -> 22 | F16: =IF($K16="","",INDEX(Calcul!$P$5:$AA$34,$K16,Calcul!$C$48)) -> 11 | G16: =IF($K16="","",IF(E16=0,"",F16/E16)) -> 0.5 | H16: =IF(G16="","",IF(G16>=Paramètres!$B$5,"● Modèle",IF(G16>=Paramètres!$B$6,"● Régulier","● Critique"))) -> ● Régulier | I16: =IF(OR($K16="",Calcul!$C$48=1),"",IF(ISNUMBER(INDEX(Calcul!$AC$5:$AN$34,$K16,MAX(1,Calcul!$C$48-1))),G16-INDEX(Calcul!$AC$5:$AN$34,$K16,MAX(1,Calcul!$C$48-1)),"")) -> 0.25 | J16: =IF($K16="","",INDEX(Calcul!$AP$5:$BA$34,$K16,Calcul!$C$48)) -> 0.5 | K16: =IFERROR(MATCH(2,Calcul!$BF$5:$BF$34,0),"") -> 6
B17: =IF($K17="","",3) -> 3 | C17: =IF($K17="","",INDEX(Calcul!$A$5:$A$34,$K17)) -> Zouhour Fathallah | D17: =IF($K17="","",IF(INDEX(Paramètres!$B$11:$B$40,$K17)="","—",INDEX(Paramètres!$B$11:$B$40,$K17))) -> QHSE Leader | E17: =IF($K17="","",INDEX(Calcul!$C$5:$N$34,$K17,Calcul!$C$48)) -> 22 | F17: =IF($K17="","",INDEX(Calcul!$P$5:$AA$34,$K17,Calcul!$C$48)) -> 7 | G17: =IF($K17="","",IF(E17=0,"",F17/E17)) -> 0.31818182 | H17: =IF(G17="","",IF(G17>=Paramètres!$B$5,"● Modèle",IF(G17>=Paramètres!$B$6,"● Régulier","● Critique"))) -> ● Critique | I17: =IF(OR($K17="",Calcul!$C$48=1),"",IF(ISNUMBER(INDEX(Calcul!$AC$5:$AN$34,$K17,MAX(1,Calcul!$C$48-1))),G17-INDEX(Calcul!$AC$5:$AN$34,$K17,MAX(1,Calcul!$C$48-1)),"")) -> -0.18181818 | J17: =IF($K17="","",INDEX(Calcul!$AP$5:$BA$34,$K17,Calcul!$C$48)) -> 0.31818182 | K17: =IFERROR(MATCH(3,Calcul!$BF$5:$BF$34,0),"") -> 18
B18: =IF($K18="","",4) -> 4 | C18: =IF($K18="","",INDEX(Calcul!$A$5:$A$34,$K18)) -> Chaima Jdid | D18: =IF($K18="","",IF(INDEX(Paramètres!$B$11:$B$40,$K18)="","—",INDEX(Paramètres!$B$11:$B$40,$K18))) -> Industerial Engeneering | E18: =IF($K18="","",INDEX(Calcul!$C$5:$N$34,$K18,Calcul!$C$48)) -> 22 | F18: =IF($K18="","",INDEX(Calcul!$P$5:$AA$34,$K18,Calcul!$C$48)) -> 7 | G18: =IF($K18="","",IF(E18=0,"",F18/E18)) -> 0.31818182 | H18: =IF(G18="","",IF(G18>=Paramètres!$B$5,"● Modèle",IF(G18>=Paramètres!$B$6,"● Régulier","● Critique"))) -> ● Critique | I18: =IF(OR($K18="",Calcul!$C$48=1),"",IF(ISNUMBER(INDEX(Calcul!$AC$5:$AN$34,$K18,MAX(1,Calcul!$C$48-1))),G18-INDEX(Calcul!$AC$5:$AN$34,$K18,MAX(1,Calcul!$C$48-1)),"")) -> -0.18181818 | J18: =IF($K18="","",INDEX(Calcul!$AP$5:$BA$34,$K18,Calcul!$C$48)) -> 0.31818182 | K18: =IFERROR(MATCH(4,Calcul!$BF$5:$BF$34,0),"") -> 4
B19: =IF($K19="","",5) -> 5 | C19: =IF($K19="","",INDEX(Calcul!$A$5:$A$34,$K19)) -> Mourad Ayari | D19: =IF($K19="","",IF(INDEX(Paramètres!$B$11:$B$40,$K19)="","—",INDEX(Paramètres!$B$11:$B$40,$K19))) -> Manufacturing Supervisor | E19: =IF($K19="","",INDEX(Calcul!$C$5:$N$34,$K19,Calcul!$C$48)) -> 22 | F19: =IF($K19="","",INDEX(Calcul!$P$5:$AA$34,$K19,Calcul!$C$48)) -> 6 | G19: =IF($K19="","",IF(E19=0,"",F19/E19)) -> 0.27272727 | H19: =IF(G19="","",IF(G19>=Paramètres!$B$5,"● Modèle",IF(G19>=Paramètres!$B$6,"● Régulier","● Critique"))) -> ● Critique | I19: =IF(OR($K19="",Calcul!$C$48=1),"",IF(ISNUMBER(INDEX(Calcul!$AC$5:$AN$34,$K19,MAX(1,Calcul!$C$48-1))),G19-INDEX(Calcul!$AC$5:$AN$34,$K19,MAX(1,Calcul!$C$48-1)),"")) -> 0.14772727 | J19: =IF($K19="","",INDEX(Calcul!$AP$5:$BA$34,$K19,Calcul!$C$48)) -> 0.27272727 | K19: =IFERROR(MATCH(5,Calcul!$BF$5:$BF$34,0),"") -> 11
B20: =IF($K20="","",6) -> 6 | C20: =IF($K20="","",INDEX(Calcul!$A$5:$A$34,$K20)) -> Marwa Solaani | D20: =IF($K20="","",IF(INDEX(Paramètres!$B$11:$B$40,$K20)="","—",INDEX(Paramètres!$B$11:$B$40,$K20))) -> Production Team Leader | E20: =IF($K20="","",INDEX(Calcul!$C$5:$N$34,$K20,Calcul!$C$48)) -> 22 | F20: =IF($K20="","",INDEX(Calcul!$P$5:$AA$34,$K20,Calcul!$C$48)) -> 6 | G20: =IF($K20="","",IF(E20=0,"",F20/E20)) -> 0.27272727 | H20: =IF(G20="","",IF(G20>=Paramètres!$B$5,"● Modèle",IF(G20>=Paramètres!$B$6,"● Régulier","● Critique"))) -> ● Critique | I20: =IF(OR($K20="",Calcul!$C$48=1),"",IF(ISNUMBER(INDEX(Calcul!$AC$5:$AN$34,$K20,MAX(1,Calcul!$C$48-1))),G20-INDEX(Calcul!$AC$5:$AN$34,$K20,MAX(1,Calcul!$C$48-1)),"")) -> -0.10227273 | J20: =IF($K20="","",INDEX(Calcul!$AP$5:$BA$34,$K20,Calcul!$C$48)) -> 0.27272727 | K20: =IFERROR(MATCH(6,Calcul!$BF$5:$BF$34,0),"") -> 8
B21: =IF($K21="","",7) -> 7 | C21: =IF($K21="","",INDEX(Calcul!$A$5:$A$34,$K21)) -> Safouen Magdouli | D21: =IF($K21="","",IF(INDEX(Paramètres!$B$11:$B$40,$K21)="","—",INDEX(Paramètres!$B$11:$B$40,$K21))) -> Leather Cutting Supervisor | E21: =IF($K21="","",INDEX(Calcul!$C$5:$N$34,$K21,Calcul!$C$48)) -> 22 | F21: =IF($K21="","",INDEX(Calcul!$P$5:$AA$34,$K21,Calcul!$C$48)) -> 4 | G21: =IF($K21="","",IF(E21=0,"",F21/E21)) -> 0.18181818 | H21: =IF(G21="","",IF(G21>=Paramètres!$B$5,"● Modèle",IF(G21>=Paramètres!$B$6,"● Régulier","● Critique"))) -> ● Critique | I21: =IF(OR($K21="",Calcul!$C$48=1),"",IF(ISNUMBER(INDEX(Calcul!$AC$5:$AN$34,$K21,MAX(1,Calcul!$C$48-1))),G21-INDEX(Calcul!$AC$5:$AN$34,$K21,MAX(1,Calcul!$C$48-1)),"")) -> -0.068181818 | J21: =IF($K21="","",INDEX(Calcul!$AP$5:$BA$34,$K21,Calcul!$C$48)) -> 0.18181818 | K21: =IFERROR(MATCH(7,Calcul!$BF$5:$BF$34,0),"") -> 15
B22: =IF($K22="","",8) -> 8 | C22: =IF($K22="","",INDEX(Calcul!$A$5:$A$34,$K22)) -> Sabrine Neffeti | D22: =IF($K22="","",IF(INDEX(Paramètres!$B$11:$B$40,$K22)="","—",INDEX(Paramètres!$B$11:$B$40,$K22))) -> Human Resources Officer | E22: =IF($K22="","",INDEX(Calcul!$C$5:$N$34,$K22,Calcul!$C$48)) -> 22 | F22: =IF($K22="","",INDEX(Calcul!$P$5:$AA$34,$K22,Calcul!$C$48)) -> 4 | G22: =IF($K22="","",IF(E22=0,"",F22/E22)) -> 0.18181818 | H22: =IF(G22="","",IF(G22>=Paramètres!$B$5,"● Modèle",IF(G22>=Paramètres!$B$6,"● Régulier","● Critique"))) -> ● Critique | I22: =IF(OR($K22="",Calcul!$C$48=1),"",IF(ISNUMBER(INDEX(Calcul!$AC$5:$AN$34,$K22,MAX(1,Calcul!$C$48-1))),G22-INDEX(Calcul!$AC$5:$AN$34,$K22,MAX(1,Calcul!$C$48-1)),"")) -> -0.068181818 | J22: =IF($K22="","",INDEX(Calcul!$AP$5:$BA$34,$K22,Calcul!$C$48)) -> 0.18181818 | K22: =IFERROR(MATCH(8,Calcul!$BF$5:$BF$34,0),"") -> 14
B23: =IF($K23="","",9) -> 9 | C23: =IF($K23="","",INDEX(Calcul!$A$5:$A$34,$K23)) -> Imre Kapusi | D23: =IF($K23="","",IF(INDEX(Paramètres!$B$11:$B$40,$K23)="","—",INDEX(Paramètres!$B$11:$B$40,$K23))) -> Manufacturing Manager | E23: =IF($K23="","",INDEX(Calcul!$C$5:$N$34,$K23,Calcul!$C$48)) -> 22 | F23: =IF($K23="","",INDEX(Calcul!$P$5:$AA$34,$K23,Calcul!$C$48)) -> 4 | G23: =IF($K23="","",IF(E23=0,"",F23/E23)) -> 0.18181818 | H23: =IF(G23="","",IF(G23>=Paramètres!$B$5,"● Modèle",IF(G23>=Paramètres!$B$6,"● Régulier","● Critique"))) -> ● Critique | I23: =IF(OR($K23="",Calcul!$C$48=1),"",IF(ISNUMBER(INDEX(Calcul!$AC$5:$AN$34,$K23,MAX(1,Calcul!$C$48-1))),G23-INDEX(Calcul!$AC$5:$AN$34,$K23,MAX(1,Calcul!$C$48-1)),"")) -> 0.18181818 | J23: =IF($K23="","",INDEX(Calcul!$AP$5:$BA$34,$K23,Calcul!$C$48)) -> 0.18181818 | K23: =IFERROR(MATCH(9,Calcul!$BF$5:$BF$34,0),"") -> 5
B24: =IF($K24="","",10) -> 10 | C24: =IF($K24="","",INDEX(Calcul!$A$5:$A$34,$K24)) -> Mina Moussa | D24: =IF($K24="","",IF(INDEX(Paramètres!$B$11:$B$40,$K24)="","—",INDEX(Paramètres!$B$11:$B$40,$K24))) -> General Manager | E24: =IF($K24="","",INDEX(Calcul!$C$5:$N$34,$K24,Calcul!$C$48)) -> 22 | F24: =IF($K24="","",INDEX(Calcul!$P$5:$AA$34,$K24,Calcul!$C$48)) -> 3 | G24: =IF($K24="","",IF(E24=0,"",F24/E24)) -> 0.13636364 | H24: =IF(G24="","",IF(G24>=Paramètres!$B$5,"● Modèle",IF(G24>=Paramètres!$B$6,"● Régulier","● Critique"))) -> ● Critique | I24: =IF(OR($K24="",Calcul!$C$48=1),"",IF(ISNUMBER(INDEX(Calcul!$AC$5:$AN$34,$K24,MAX(1,Calcul!$C$48-1))),G24-INDEX(Calcul!$AC$5:$AN$34,$K24,MAX(1,Calcul!$C$48-1)),"")) -> 0.011363636 | J24: =IF($K24="","",INDEX(Calcul!$AP$5:$BA$34,$K24,Calcul!$C$48)) -> 0.13636364 | K24: =IFERROR(MATCH(10,Calcul!$BF$5:$BF$34,0),"") -> 9
B25: =IF($K25="","",11) -> 11 | C25: =IF($K25="","",INDEX(Calcul!$A$5:$A$34,$K25)) -> Nouha Ben Khlifa | D25: =IF($K25="","",IF(INDEX(Paramètres!$B$11:$B$40,$K25)="","—",INDEX(Paramètres!$B$11:$B$40,$K25))) -> Time & Methods Analyst | E25: =IF($K25="","",INDEX(Calcul!$C$5:$N$34,$K25,Calcul!$C$48)) -> 22 | F25: =IF($K25="","",INDEX(Calcul!$P$5:$AA$34,$K25,Calcul!$C$48)) -> 2 | G25: =IF($K25="","",IF(E25=0,"",F25/E25)) -> 0.090909091 | H25: =IF(G25="","",IF(G25>=Paramètres!$B$5,"● Modèle",IF(G25>=Paramètres!$B$6,"● Régulier","● Critique"))) -> ● Critique | I25: =IF(OR($K25="",Calcul!$C$48=1),"",IF(ISNUMBER(INDEX(Calcul!$AC$5:$AN$34,$K25,MAX(1,Calcul!$C$48-1))),G25-INDEX(Calcul!$AC$5:$AN$34,$K25,MAX(1,Calcul!$C$48-1)),"")) -> -0.034090909 | J25: =IF($K25="","",INDEX(Calcul!$AP$5:$BA$34,$K25,Calcul!$C$48)) -> 0.090909091 | K25: =IFERROR(MATCH(11,Calcul!$BF$5:$BF$34,0),"") -> 13
B26: =IF($K26="","",12) -> 12 | C26: =IF($K26="","",INDEX(Calcul!$A$5:$A$34,$K26)) -> Mohamed Sniha | D26: =IF($K26="","",IF(INDEX(Paramètres!$B$11:$B$40,$K26)="","—",INDEX(Paramètres!$B$11:$B$40,$K26))) -> Administrative and financial Manager | E26: =IF($K26="","",INDEX(Calcul!$C$5:$N$34,$K26,Calcul!$C$48)) -> 22 | F26: =IF($K26="","",INDEX(Calcul!$P$5:$AA$34,$K26,Calcul!$C$48)) -> 1 | G26: =IF($K26="","",IF(E26=0,"",F26/E26)) -> 0.045454545 | H26: =IF(G26="","",IF(G26>=Paramètres!$B$5,"● Modèle",IF(G26>=Paramètres!$B$6,"● Régulier","● Critique"))) -> ● Critique | I26: =IF(OR($K26="",Calcul!$C$48=1),"",IF(ISNUMBER(INDEX(Calcul!$AC$5:$AN$34,$K26,MAX(1,Calcul!$C$48-1))),G26-INDEX(Calcul!$AC$5:$AN$34,$K26,MAX(1,Calcul!$C$48-1)),"")) -> -0.079545455 | J26: =IF($K26="","",INDEX(Calcul!$AP$5:$BA$34,$K26,Calcul!$C$48)) -> 0.045454545 | K26: =IFERROR(MATCH(12,Calcul!$BF$5:$BF$34,0),"") -> 10
B27: =IF($K27="","",13) -> 13 | C27: =IF($K27="","",INDEX(Calcul!$A$5:$A$34,$K27)) -> Wissem Ben Abdalah | D27: =IF($K27="","",IF(INDEX(Paramètres!$B$11:$B$40,$K27)="","—",INDEX(Paramètres!$B$11:$B$40,$K27))) -> StoreKeeper | E27: =IF($K27="","",INDEX(Calcul!$C$5:$N$34,$K27,Calcul!$C$48)) -> 22 | F27: =IF($K27="","",INDEX(Calcul!$P$5:$AA$34,$K27,Calcul!$C$48)) -> 0 | G27: =IF($K27="","",IF(E27=0,"",F27/E27)) -> 0 | H27: =IF(G27="","",IF(G27>=Paramètres!$B$5,"● Modèle",IF(G27>=Paramètres!$B$6,"● Régulier","● Critique"))) -> ● Critique | I27: =IF(OR($K27="",Calcul!$C$48=1),"",IF(ISNUMBER(INDEX(Calcul!$AC$5:$AN$34,$K27,MAX(1,Calcul!$C$48-1))),G27-INDEX(Calcul!$AC$5:$AN$34,$K27,MAX(1,Calcul!$C$48-1)),"")) -> -0.125 | J27: =IF($K27="","",INDEX(Calcul!$AP$5:$BA$34,$K27,Calcul!$C$48)) -> 0 | K27: =IFERROR(MATCH(13,Calcul!$BF$5:$BF$34,0),"") -> 17
B28: =IF($K28="","",14) -> 14 | C28: =IF($K28="","",INDEX(Calcul!$A$5:$A$34,$K28)) -> Lobna Jberi | D28: =IF($K28="","",IF(INDEX(Paramètres!$B$11:$B$40,$K28)="","—",INDEX(Paramètres!$B$11:$B$40,$K28))) -> Purchaser & Imp/Exp Agent | E28: =IF($K28="","",INDEX(Calcul!$C$5:$N$34,$K28,Calcul!$C$48)) -> 22 | F28: =IF($K28="","",INDEX(Calcul!$P$5:$AA$34,$K28,Calcul!$C$48)) -> 0 | G28: =IF($K28="","",IF(E28=0,"",F28/E28)) -> 0 | H28: =IF(G28="","",IF(G28>=Paramètres!$B$5,"● Modèle",IF(G28>=Paramètres!$B$6,"● Régulier","● Critique"))) -> ● Critique | I28: =IF(OR($K28="",Calcul!$C$48=1),"",IF(ISNUMBER(INDEX(Calcul!$AC$5:$AN$34,$K28,MAX(1,Calcul!$C$48-1))),G28-INDEX(Calcul!$AC$5:$AN$34,$K28,MAX(1,Calcul!$C$48-1)),"")) -> -0.125 | J28: =IF($K28="","",INDEX(Calcul!$AP$5:$BA$34,$K28,Calcul!$C$48)) -> 0 | K28: =IFERROR(MATCH(14,Calcul!$BF$5:$BF$34,0),"") -> 7
B29: =IF($K29="","",15) -> 15 | C29: =IF($K29="","",INDEX(Calcul!$A$5:$A$34,$K29)) -> Amine Latrech | D29: =IF($K29="","",IF(INDEX(Paramètres!$B$11:$B$40,$K29)="","—",INDEX(Paramètres!$B$11:$B$40,$K29))) -> Head of Maintenance | E29: =IF($K29="","",INDEX(Calcul!$C$5:$N$34,$K29,Calcul!$C$48)) -> 22 | F29: =IF($K29="","",INDEX(Calcul!$P$5:$AA$34,$K29,Calcul!$C$48)) -> 0 | G29: =IF($K29="","",IF(E29=0,"",F29/E29)) -> 0 | H29: =IF(G29="","",IF(G29>=Paramètres!$B$5,"● Modèle",IF(G29>=Paramètres!$B$6,"● Régulier","● Critique"))) -> ● Critique | I29: =IF(OR($K29="",Calcul!$C$48=1),"",IF(ISNUMBER(INDEX(Calcul!$AC$5:$AN$34,$K29,MAX(1,Calcul!$C$48-1))),G29-INDEX(Calcul!$AC$5:$AN$34,$K29,MAX(1,Calcul!$C$48-1)),"")) -> 0 | J29: =IF($K29="","",INDEX(Calcul!$AP$5:$BA$34,$K29,Calcul!$C$48)) -> 0 | K29: =IFERROR(MATCH(15,Calcul!$BF$5:$BF$34,0),"") -> 3
B30: =IF($K30="","",16) | C30: =IF($K30="","",INDEX(Calcul!$A$5:$A$34,$K30)) | D30: =IF($K30="","",IF(INDEX(Paramètres!$B$11:$B$40,$K30)="","—",INDEX(Paramètres!$B$11:$B$40,$K30))) | E30: =IF($K30="","",INDEX(Calcul!$C$5:$N$34,$K30,Calcul!$C$48)) | F30: =IF($K30="","",INDEX(Calcul!$P$5:$AA$34,$K30,Calcul!$C$48)) | G30: =IF($K30="","",IF(E30=0,"",F30/E30)) | H30: =IF(G30="","",IF(G30>=Paramètres!$B$5,"● Modèle",IF(G30>=Paramètres!$B$6,"● Régulier","● Critique"))) | I30: =IF(OR($K30="",Calcul!$C$48=1),"",IF(ISNUMBER(INDEX(Calcul!$AC$5:$AN$34,$K30,MAX(1,Calcul!$C$48-1))),G30-INDEX(Calcul!$AC$5:$AN$34,$K30,MAX(1,Calcul!$C$48-1)),"")) | J30: =IF($K30="","",INDEX(Calcul!$AP$5:$BA$34,$K30,Calcul!$C$48)) | K30: =IFERROR(MATCH(16,Calcul!$BF$5:$BF$34,0),"")
B31: =IF($K31="","",17) | C31: =IF($K31="","",INDEX(Calcul!$A$5:$A$34,$K31)) | D31: =IF($K31="","",IF(INDEX(Paramètres!$B$11:$B$40,$K31)="","—",INDEX(Paramètres!$B$11:$B$40,$K31))) | E31: =IF($K31="","",INDEX(Calcul!$C$5:$N$34,$K31,Calcul!$C$48)) | F31: =IF($K31="","",INDEX(Calcul!$P$5:$AA$34,$K31,Calcul!$C$48)) | G31: =IF($K31="","",IF(E31=0,"",F31/E31)) | H31: =IF(G31="","",IF(G31>=Paramètres!$B$5,"● Modèle",IF(G31>=Paramètres!$B$6,"● Régulier","● Critique"))) | I31: =IF(OR($K31="",Calcul!$C$48=1),"",IF(ISNUMBER(INDEX(Calcul!$AC$5:$AN$34,$K31,MAX(1,Calcul!$C$48-1))),G31-INDEX(Calcul!$AC$5:$AN$34,$K31,MAX(1,Calcul!$C$48-1)),"")) | J31: =IF($K31="","",INDEX(Calcul!$AP$5:$BA$34,$K31,Calcul!$C$48)) | K31: =IFERROR(MATCH(17,Calcul!$BF$5:$BF$34,0),"")
B32: =IF($K32="","",18) | C32: =IF($K32="","",INDEX(Calcul!$A$5:$A$34,$K32)) | D32: =IF($K32="","",IF(INDEX(Paramètres!$B$11:$B$40,$K32)="","—",INDEX(Paramètres!$B$11:$B$40,$K32))) | E32: =IF($K32="","",INDEX(Calcul!$C$5:$N$34,$K32,Calcul!$C$48)) | F32: =IF($K32="","",INDEX(Calcul!$P$5:$AA$34,$K32,Calcul!$C$48)) | G32: =IF($K32="","",IF(E32=0,"",F32/E32)) | H32: =IF(G32="","",IF(G32>=Paramètres!$B$5,"● Modèle",IF(G32>=Paramètres!$B$6,"● Régulier","● Critique"))) | I32: =IF(OR($K32="",Calcul!$C$48=1),"",IF(ISNUMBER(INDEX(Calcul!$AC$5:$AN$34,$K32,MAX(1,Calcul!$C$48-1))),G32-INDEX(Calcul!$AC$5:$AN$34,$K32,MAX(1,Calcul!$C$48-1)),"")) | J32: =IF($K32="","",INDEX(Calcul!$AP$5:$BA$34,$K32,Calcul!$C$48)) | K32: =IFERROR(MATCH(18,Calcul!$BF$5:$BF$34,0),"")
B33: =IF($K33="","",19) | C33: =IF($K33="","",INDEX(Calcul!$A$5:$A$34,$K33)) | D33: =IF($K33="","",IF(INDEX(Paramètres!$B$11:$B$40,$K33)="","—",INDEX(Paramètres!$B$11:$B$40,$K33))) | E33: =IF($K33="","",INDEX(Calcul!$C$5:$N$34,$K33,Calcul!$C$48)) | F33: =IF($K33="","",INDEX(Calcul!$P$5:$AA$34,$K33,Calcul!$C$48)) | G33: =IF($K33="","",IF(E33=0,"",F33/E33)) | H33: =IF(G33="","",IF(G33>=Paramètres!$B$5,"● Modèle",IF(G33>=Paramètres!$B$6,"● Régulier","● Critique"))) | I33: =IF(OR($K33="",Calcul!$C$48=1),"",IF(ISNUMBER(INDEX(Calcul!$AC$5:$AN$34,$K33,MAX(1,Calcul!$C$48-1))),G33-INDEX(Calcul!$AC$5:$AN$34,$K33,MAX(1,Calcul!$C$48-1)),"")) | J33: =IF($K33="","",INDEX(Calcul!$AP$5:$BA$34,$K33,Calcul!$C$48)) | K33: =IFERROR(MATCH(19,Calcul!$BF$5:$BF$34,0),"")
B34: =IF($K34="","",20) | C34: =IF($K34="","",INDEX(Calcul!$A$5:$A$34,$K34)) | D34: =IF($K34="","",IF(INDEX(Paramètres!$B$11:$B$40,$K34)="","—",INDEX(Paramètres!$B$11:$B$40,$K34))) | E34: =IF($K34="","",INDEX(Calcul!$C$5:$N$34,$K34,Calcul!$C$48)) | F34: =IF($K34="","",INDEX(Calcul!$P$5:$AA$34,$K34,Calcul!$C$48)) | G34: =IF($K34="","",IF(E34=0,"",F34/E34)) | H34: =IF(G34="","",IF(G34>=Paramètres!$B$5,"● Modèle",IF(G34>=Paramètres!$B$6,"● Régulier","● Critique"))) | I34: =IF(OR($K34="",Calcul!$C$48=1),"",IF(ISNUMBER(INDEX(Calcul!$AC$5:$AN$34,$K34,MAX(1,Calcul!$C$48-1))),G34-INDEX(Calcul!$AC$5:$AN$34,$K34,MAX(1,Calcul!$C$48-1)),"")) | J34: =IF($K34="","",INDEX(Calcul!$AP$5:$BA$34,$K34,Calcul!$C$48)) | K34: =IFERROR(MATCH(20,Calcul!$BF$5:$BF$34,0),"")
B35: =IF($K35="","",21) | C35: =IF($K35="","",INDEX(Calcul!$A$5:$A$34,$K35)) | D35: =IF($K35="","",IF(INDEX(Paramètres!$B$11:$B$40,$K35)="","—",INDEX(Paramètres!$B$11:$B$40,$K35))) | E35: =IF($K35="","",INDEX(Calcul!$C$5:$N$34,$K35,Calcul!$C$48)) | F35: =IF($K35="","",INDEX(Calcul!$P$5:$AA$34,$K35,Calcul!$C$48)) | G35: =IF($K35="","",IF(E35=0,"",F35/E35)) | H35: =IF(G35="","",IF(G35>=Paramètres!$B$5,"● Modèle",IF(G35>=Paramètres!$B$6,"● Régulier","● Critique"))) | I35: =IF(OR($K35="",Calcul!$C$48=1),"",IF(ISNUMBER(INDEX(Calcul!$AC$5:$AN$34,$K35,MAX(1,Calcul!$C$48-1))),G35-INDEX(Calcul!$AC$5:$AN$34,$K35,MAX(1,Calcul!$C$48-1)),"")) | J35: =IF($K35="","",INDEX(Calcul!$AP$5:$BA$34,$K35,Calcul!$C$48)) | K35: =IFERROR(MATCH(21,Calcul!$BF$5:$BF$34,0),"")
B36: =IF($K36="","",22) | C36: =IF($K36="","",INDEX(Calcul!$A$5:$A$34,$K36)) | D36: =IF($K36="","",IF(INDEX(Paramètres!$B$11:$B$40,$K36)="","—",INDEX(Paramètres!$B$11:$B$40,$K36))) | E36: =IF($K36="","",INDEX(Calcul!$C$5:$N$34,$K36,Calcul!$C$48)) | F36: =IF($K36="","",INDEX(Calcul!$P$5:$AA$34,$K36,Calcul!$C$48)) | G36: =IF($K36="","",IF(E36=0,"",F36/E36)) | H36: =IF(G36="","",IF(G36>=Paramètres!$B$5,"● Modèle",IF(G36>=Paramètres!$B$6,"● Régulier","● Critique"))) | I36: =IF(OR($K36="",Calcul!$C$48=1),"",IF(ISNUMBER(INDEX(Calcul!$AC$5:$AN$34,$K36,MAX(1,Calcul!$C$48-1))),G36-INDEX(Calcul!$AC$5:$AN$34,$K36,MAX(1,Calcul!$C$48-1)),"")) | J36: =IF($K36="","",INDEX(Calcul!$AP$5:$BA$34,$K36,Calcul!$C$48)) | K36: =IFERROR(MATCH(22,Calcul!$BF$5:$BF$34,0),"")
B37: =IF($K37="","",23) | C37: =IF($K37="","",INDEX(Calcul!$A$5:$A$34,$K37)) | D37: =IF($K37="","",IF(INDEX(Paramètres!$B$11:$B$40,$K37)="","—",INDEX(Paramètres!$B$11:$B$40,$K37))) | E37: =IF($K37="","",INDEX(Calcul!$C$5:$N$34,$K37,Calcul!$C$48)) | F37: =IF($K37="","",INDEX(Calcul!$P$5:$AA$34,$K37,Calcul!$C$48)) | G37: =IF($K37="","",IF(E37=0,"",F37/E37)) | H37: =IF(G37="","",IF(G37>=Paramètres!$B$5,"● Modèle",IF(G37>=Paramètres!$B$6,"● Régulier","● Critique"))) | I37: =IF(OR($K37="",Calcul!$C$48=1),"",IF(ISNUMBER(INDEX(Calcul!$AC$5:$AN$34,$K37,MAX(1,Calcul!$C$48-1))),G37-INDEX(Calcul!$AC$5:$AN$34,$K37,MAX(1,Calcul!$C$48-1)),"")) | J37: =IF($K37="","",INDEX(Calcul!$AP$5:$BA$34,$K37,Calcul!$C$48)) | K37: =IFERROR(MATCH(23,Calcul!$BF$5:$BF$34,0),"")
B38: =IF($K38="","",24) | C38: =IF($K38="","",INDEX(Calcul!$A$5:$A$34,$K38)) | D38: =IF($K38="","",IF(INDEX(Paramètres!$B$11:$B$40,$K38)="","—",INDEX(Paramètres!$B$11:$B$40,$K38))) | E38: =IF($K38="","",INDEX(Calcul!$C$5:$N$34,$K38,Calcul!$C$48)) | F38: =IF($K38="","",INDEX(Calcul!$P$5:$AA$34,$K38,Calcul!$C$48)) | G38: =IF($K38="","",IF(E38=0,"",F38/E38)) | H38: =IF(G38="","",IF(G38>=Paramètres!$B$5,"● Modèle",IF(G38>=Paramètres!$B$6,"● Régulier","● Critique"))) | I38: =IF(OR($K38="",Calcul!$C$48=1),"",IF(ISNUMBER(INDEX(Calcul!$AC$5:$AN$34,$K38,MAX(1,Calcul!$C$48-1))),G38-INDEX(Calcul!$AC$5:$AN$34,$K38,MAX(1,Calcul!$C$48-1)),"")) | J38: =IF($K38="","",INDEX(Calcul!$AP$5:$BA$34,$K38,Calcul!$C$48)) | K38: =IFERROR(MATCH(24,Calcul!$BF$5:$BF$34,0),"")
B39: =IF($K39="","",25) | C39: =IF($K39="","",INDEX(Calcul!$A$5:$A$34,$K39)) | D39: =IF($K39="","",IF(INDEX(Paramètres!$B$11:$B$40,$K39)="","—",INDEX(Paramètres!$B$11:$B$40,$K39))) | E39: =IF($K39="","",INDEX(Calcul!$C$5:$N$34,$K39,Calcul!$C$48)) | F39: =IF($K39="","",INDEX(Calcul!$P$5:$AA$34,$K39,Calcul!$C$48)) | G39: =IF($K39="","",IF(E39=0,"",F39/E39)) | H39: =IF(G39="","",IF(G39>=Paramètres!$B$5,"● Modèle",IF(G39>=Paramètres!$B$6,"● Régulier","● Critique"))) | I39: =IF(OR($K39="",Calcul!$C$48=1),"",IF(ISNUMBER(INDEX(Calcul!$AC$5:$AN$34,$K39,MAX(1,Calcul!$C$48-1))),G39-INDEX(Calcul!$AC$5:$AN$34,$K39,MAX(1,Calcul!$C$48-1)),"")) | J39: =IF($K39="","",INDEX(Calcul!$AP$5:$BA$34,$K39,Calcul!$C$48)) | K39: =IFERROR(MATCH(25,Calcul!$BF$5:$BF$34,0),"")
B40: =IF($K40="","",26) | C40: =IF($K40="","",INDEX(Calcul!$A$5:$A$34,$K40)) | D40: =IF($K40="","",IF(INDEX(Paramètres!$B$11:$B$40,$K40)="","—",INDEX(Paramètres!$B$11:$B$40,$K40))) | E40: =IF($K40="","",INDEX(Calcul!$C$5:$N$34,$K40,Calcul!$C$48)) | F40: =IF($K40="","",INDEX(Calcul!$P$5:$AA$34,$K40,Calcul!$C$48)) | G40: =IF($K40="","",IF(E40=0,"",F40/E40)) | H40: =IF(G40="","",IF(G40>=Paramètres!$B$5,"● Modèle",IF(G40>=Paramètres!$B$6,"● Régulier","● Critique"))) | I40: =IF(OR($K40="",Calcul!$C$48=1),"",IF(ISNUMBER(INDEX(Calcul!$AC$5:$AN$34,$K40,MAX(1,Calcul!$C$48-1))),G40-INDEX(Calcul!$AC$5:$AN$34,$K40,MAX(1,Calcul!$C$48-1)),"")) | J40: =IF($K40="","",INDEX(Calcul!$AP$5:$BA$34,$K40,Calcul!$C$48)) | K40: =IFERROR(MATCH(26,Calcul!$BF$5:$BF$34,0),"")
B41: =IF($K41="","",27) | C41: =IF($K41="","",INDEX(Calcul!$A$5:$A$34,$K41)) | D41: =IF($K41="","",IF(INDEX(Paramètres!$B$11:$B$40,$K41)="","—",INDEX(Paramètres!$B$11:$B$40,$K41))) | E41: =IF($K41="","",INDEX(Calcul!$C$5:$N$34,$K41,Calcul!$C$48)) | F41: =IF($K41="","",INDEX(Calcul!$P$5:$AA$34,$K41,Calcul!$C$48)) | G41: =IF($K41="","",IF(E41=0,"",F41/E41)) | H41: =IF(G41="","",IF(G41>=Paramètres!$B$5,"● Modèle",IF(G41>=Paramètres!$B$6,"● Régulier","● Critique"))) | I41: =IF(OR($K41="",Calcul!$C$48=1),"",IF(ISNUMBER(INDEX(Calcul!$AC$5:$AN$34,$K41,MAX(1,Calcul!$C$48-1))),G41-INDEX(Calcul!$AC$5:$AN$34,$K41,MAX(1,Calcul!$C$48-1)),"")) | J41: =IF($K41="","",INDEX(Calcul!$AP$5:$BA$34,$K41,Calcul!$C$48)) | K41: =IFERROR(MATCH(27,Calcul!$BF$5:$BF$34,0),"")
B42: =IF($K42="","",28) | C42: =IF($K42="","",INDEX(Calcul!$A$5:$A$34,$K42)) | D42: =IF($K42="","",IF(INDEX(Paramètres!$B$11:$B$40,$K42)="","—",INDEX(Paramètres!$B$11:$B$40,$K42))) | E42: =IF($K42="","",INDEX(Calcul!$C$5:$N$34,$K42,Calcul!$C$48)) | F42: =IF($K42="","",INDEX(Calcul!$P$5:$AA$34,$K42,Calcul!$C$48)) | G42: =IF($K42="","",IF(E42=0,"",F42/E42)) | H42: =IF(G42="","",IF(G42>=Paramètres!$B$5,"● Modèle",IF(G42>=Paramètres!$B$6,"● Régulier","● Critique"))) | I42: =IF(OR($K42="",Calcul!$C$48=1),"",IF(ISNUMBER(INDEX(Calcul!$AC$5:$AN$34,$K42,MAX(1,Calcul!$C$48-1))),G42-INDEX(Calcul!$AC$5:$AN$34,$K42,MAX(1,Calcul!$C$48-1)),"")) | J42: =IF($K42="","",INDEX(Calcul!$AP$5:$BA$34,$K42,Calcul!$C$48)) | K42: =IFERROR(MATCH(28,Calcul!$BF$5:$BF$34,0),"")
B43: =IF($K43="","",29) | C43: =IF($K43="","",INDEX(Calcul!$A$5:$A$34,$K43)) | D43: =IF($K43="","",IF(INDEX(Paramètres!$B$11:$B$40,$K43)="","—",INDEX(Paramètres!$B$11:$B$40,$K43))) | E43: =IF($K43="","",INDEX(Calcul!$C$5:$N$34,$K43,Calcul!$C$48)) | F43: =IF($K43="","",INDEX(Calcul!$P$5:$AA$34,$K43,Calcul!$C$48)) | G43: =IF($K43="","",IF(E43=0,"",F43/E43)) | H43: =IF(G43="","",IF(G43>=Paramètres!$B$5,"● Modèle",IF(G43>=Paramètres!$B$6,"● Régulier","● Critique"))) | I43: =IF(OR($K43="",Calcul!$C$48=1),"",IF(ISNUMBER(INDEX(Calcul!$AC$5:$AN$34,$K43,MAX(1,Calcul!$C$48-1))),G43-INDEX(Calcul!$AC$5:$AN$34,$K43,MAX(1,Calcul!$C$48-1)),"")) | J43: =IF($K43="","",INDEX(Calcul!$AP$5:$BA$34,$K43,Calcul!$C$48)) | K43: =IFERROR(MATCH(29,Calcul!$BF$5:$BF$34,0),"")
B44: =IF($K44="","",30) | C44: =IF($K44="","",INDEX(Calcul!$A$5:$A$34,$K44)) | D44: =IF($K44="","",IF(INDEX(Paramètres!$B$11:$B$40,$K44)="","—",INDEX(Paramètres!$B$11:$B$40,$K44))) | E44: =IF($K44="","",INDEX(Calcul!$C$5:$N$34,$K44,Calcul!$C$48)) | F44: =IF($K44="","",INDEX(Calcul!$P$5:$AA$34,$K44,Calcul!$C$48)) | G44: =IF($K44="","",IF(E44=0,"",F44/E44)) | H44: =IF(G44="","",IF(G44>=Paramètres!$B$5,"● Modèle",IF(G44>=Paramètres!$B$6,"● Régulier","● Critique"))) | I44: =IF(OR($K44="",Calcul!$C$48=1),"",IF(ISNUMBER(INDEX(Calcul!$AC$5:$AN$34,$K44,MAX(1,Calcul!$C$48-1))),G44-INDEX(Calcul!$AC$5:$AN$34,$K44,MAX(1,Calcul!$C$48-1)),"")) | J44: =IF($K44="","",INDEX(Calcul!$AP$5:$BA$34,$K44,Calcul!$C$48)) | K44: =IFERROR(MATCH(30,Calcul!$BF$5:$BF$34,0),"")
B46: Contrôles qualité des données
B47: Lignes importées dans le journal | H47: =COUNTA(Journal!B2:B3001) -> 922
...

Sheet Paramètres
A1: PARAMÈTRES — effectif, seuils et calendrier
A2: Cellules sur fond jaune = à renseigner / confirmer. Tout le reste se calcule automatiquement.
A4: Seuils
A5: Objectif atteint (taux ≥) | B5: 0.7
A6: Alerte (taux ≥, sinon Critique) | B6: 0.4
A7: Cible direction : jours consultés par jour ouvré | B7: 1 | C7: Information : le taux = jours avec ≥1 accès ÷ jours ouvrés attendus.
A8: Année de suivi | B8: 2026
H9: Jours non ouvrés (fériés / fermetures) — en plus des samedis et dimanches | K9: Mots de mois reconnus dans l'export
A10: Responsable (nom exact du journal) | B10: Fonction / rôle | C10: Date début | D10: Date fin | E10: Cible individuelle (jours/semaine) | F10: Note | H10: Date | I10: Motif / source | K10: Mot | L10: N°
A11: Ahlem Moussa | B11: Quality Inspector | E11: 5 | H11: 46023 | I11: Jour de l'An (jour férié légal ; aucun accès au journal) | K11: janv | L11: 1
A12: Amani Nasser | B12: Purchaser & Imp/Exp Agent | D12: 46142 | E12: 5 | F12: Départ (Améni). Date de fin = fin du mois de son dernier accès (13/04) — À CONFIRMER | H12: 46101 | I12: Fête de l'Indépendance + Aïd el-Fitr (20, 21 et 22 mars) | K12: janvier | L12: 1
A13: Amine Latrech | B13: Head of Maintenance | E13: 5 | H13: 46143 | I13: Fête du Travail | K13: févr | L13: 2
A14: Chaima Jdid | B14: Industerial Engeneering | C14: 46204 | D14: 46295 | E14: 5 | F14: Nouvelle recrue, contrat juin→septembre (1er accès journal : 09/07) | H14: 46169 | I14: Aïd el-Adha (mercredi 27 au samedi 30 mai) | K14: fevr | L14: 2
A15: Imre Kapusi | B15: Manufacturing Manager | E15: 5 | H15: 46170 | I15: Aïd el-Adha (mercredi 27 au samedi 30 mai) | K15: février | L15: 2
A16: Ines Farhat | B16: Quality Control & PACK Supervisor | E16: 5 | H16: 46171 | I16: Aïd el-Adha (mercredi 27 au samedi 30 mai) | K16: mars | L16: 3
A17: Lobna Jberi | B17: Purchaser & Imp/Exp Agent | C17: 46204 | E17: 5 | F17: Remplaçante d'Amani Nasser — date de début À CONFIRMER (aucun accès en septembre) | H17: 46244 | I17: Fermeture estivale du 09/08 au 26/08/2026 | K17: avr | L17: 4
A18: Marwa Solaani | B18: Production Team Leader | E18: 5 | H18: 46245 | I18: Fermeture estivale du 09/08 au 26/08/2026 | K18: avril | L18: 4
A19: Mina Moussa | B19: General Manager | E19: 5 | H19: 46246 | I19: Fermeture estivale du 09/08 au 26/08/2026 | K19: mai | L19: 5
A20: Mohamed Sniha | B20: Administrative and financial Manager | E20: 5 | H20: 46247 | I20: Fermeture estivale du 09/08 au 26/08/2026 | K20: juin | L20: 6
A21: Mourad Ayari | B21: Manufacturing Supervisor | E21: 5 | H21: 46248 | I21: Fermeture estivale du 09/08 au 26/08/2026 | K21: juil | L21: 7
A22: Nesrine Laassili | B22: planning | D22: 46112 | E22: 5 | F22: Sortie de la société (dernier accès 27/03) — date de fin À CONFIRMER | H22: 46251 | I22: Fermeture estivale du 09/08 au 26/08/2026 | K22: juillet | L22: 7
A23: Nouha Ben Khlifa | B23: Time & Methods Analyst | C23: 46204 | E23: 5 | F23: Arrivée juillet (1er accès 06/07) — date de début À CONFIRMER | H23: 46252 | I23: Fermeture estivale du 09/08 au 26/08/2026 | K23: août | L23: 8
A24: Sabrine Neffeti | B24: Human Resources Officer | E24: 5 | H24: 46253 | I24: Fermeture estivale du 09/08 au 26/08/2026 | K24: aout | L24: 8
A25: Safouen Magdouli | B25: Leather Cutting Supervisor | E25: 5 | H25: 46254 | I25: Fermeture estivale du 09/08 au 26/08/2026 | K25: sept | L25: 9
A26: Said Hamrouni | B26: Planning & Logistics Manager | D26: 46203 | E26: 5 | F26: Départ. Date de fin = fin du mois de son dernier accès (24/06) — À CONFIRMER | H26: 46255 | I26: Fermeture estivale du 09/08 au 26/08/2026 | K26: septembre | L26: 9
A27: Wissem Ben Abdalah | B27: StoreKeeper | E27: 5 | H27: 46258 | I27: Fermeture estivale du 09/08 au 26/08/2026 | K27: oct | L27: 10
A28: Zouhour Fathallah | B28: QHSE Leader | E28: 5 | H28: 46259 | I28: Fermeture estivale du 09/08 au 26/08/2026 | K28: octobre | L28: 10
H29: 46260 | I29: Fermeture estivale du 09/08 au 26/08/2026 | K29: nov | L29: 11
K30: novembre | L30: 11
K31: déc | L31: 12
K32: dec | L32: 12
K33: décembre | L33: 12
A41: Lignes 11 à 40 : ajoutez ici chaque nouvel utilisateur (dates début/fin = période pendant laquelle il doit utiliser Qualipro). Cible individuelle : 5 = quotidien (cible direction) ; ex. 2 = deux jours par semaine pour un rôle ponctuel.

Sheet Journal
A1: Matricule (optionnel) | B1: Nom | C1: Date et heure (copie de l'export) | D1: Nom nettoyé | E1: Mois (mot) | F1: Jour | G1: Année | H1: Date | I1: 1er accès du jour (1=oui) | J1: Jour ouvré | K1: Compté (1er accès × jour ouvré) | L1: Connu dans l'effectif | N1: MISE À JOUR MENSUELLE : collez l'export brut (sans dédoublonner) dans les colonnes B et C à la suite des lignes existantes. Tout le reste se calcule (jusqu'à la ligne 3001).
B2: Mina Moussa | C2: janv 02 2026 7:58AM | D2: =IF(B2="","",TRIM(B2)) -> Mina Moussa | E2: =IF($C2="","",LEFT($C2,FIND(" ",$C2)-1)) -> janv | F2: =IF($C2="","",IFERROR(VALUE(LEFT(MID($C2,FIND(" ",$C2)+1,20),FIND(" ",MID($C2,FIND(" ",$C2)+1,20))-1)),"?")) -> 2 | G2: =IF($C2="","",IFERROR(VALUE(MID(MID($C2,FIND(" ",$C2)+1,20),FIND(" ",MID($C2,FIND(" ",$C2)+1,20))+1,4)),"?")) -> 2026 | H2: =IF($C2="","",IFERROR(DATE(G2,VLOOKUP(E2,Paramètres!$K$11:$L$40,2,FALSE()),F2),"?")) -> 46024 | I2: =IF(ISNUMBER(H2),IF(COUNTIFS($D$2:D2,D2,$H$2:H2,H2)=1,1,0),"") -> 1 | J2: =IF(ISNUMBER(H2),IFERROR(INDEX(Calendrier!$C$2:$C$367,MATCH(H2,Calendrier!$A$2:$A$367,0)),0),"") -> 1 | K2: =IF(ISNUMBER(H2),I2*J2,"") -> 1 | L2: =IF(D2="","",IF(COUNTIF(Paramètres!$A$11:$A$40,D2)>0,1,0)) -> 1
B3: Mina Moussa | C3: janv 02 2026 8:03AM | D3: =IF(B3="","",TRIM(B3)) -> Mina Moussa | E3: =IF($C3="","",LEFT($C3,FIND(" ",$C3)-1)) -> janv | F3: =IF($C3="","",IFERROR(VALUE(LEFT(MID($C3,FIND(" ",$C3)+1,20),FIND(" ",MID($C3,FIND(" ",$C3)+1,20))-1)),"?")) -> 2 | G3: =IF($C3="","",IFERROR(VALUE(MID(MID($C3,FIND(" ",$C3)+1,20),FIND(" ",MID($C3,FIND(" ",$C3)+1,20))+1,4)),"?")) -> 2026 | H3: =IF($C3="","",IFERROR(DATE(G3,VLOOKUP(E3,Paramètres!$K$11:$L$40,2,FALSE()),F3),"?")) -> 46024 | I3: =IF(ISNUMBER(H3),IF(COUNTIFS($D$2:D3,D3,$H$2:H3,H3)=1,1,0),"") -> 0 | J3: =IF(ISNUMBER(H3),IFERROR(INDEX(Calendrier!$C$2:$C$367,MATCH(H3,Calendrier!$A$2:$A$367,0)),0),"") -> 1 | K3: =IF(ISNUMBER(H3),I3*J3,"") -> 0 | L3: =IF(D3="","",IF(COUNTIF(Paramètres!$A$11:$A$40,D3)>0,1,0)) -> 1
B4: Mina Moussa | C4: janv 02 2026 9:20AM | D4: =IF(B4="","",TRIM(B4)) -> Mina Moussa | E4: =IF($C4="","",LEFT($C4,FIND(" ",$C4)-1)) -> janv | F4: =IF($C4="","",IFERROR(VALUE(LEFT(MID($C4,FIND(" ",$C4)+1,20),FIND(" ",MID($C4,FIND(" ",$C4)+1,20))-1)),"?")) -> 2 | G4: =IF($C4="","",IFERROR(VALUE(MID(MID($C4,FIND(" ",$C4)+1,20),FIND(" ",MID($C4,FIND(" ",$C4)+1,20))+1,4)),"?")) -> 2026 | H4: =IF($C4="","",IFERROR(DATE(G4,VLOOKUP(E4,Paramètres!$K$11:$L$40,2,FALSE()),F4),"?")) -> 46024 | I4: =IF(ISNUMBER(H4),IF(COUNTIFS($D$2:D4,D4,$H$2:H4,H4)=1,1,0),"") -> 0 | J4: =IF(ISNUMBER(H4),IFERROR(INDEX(Calendrier!$C$2:$C$367,MATCH(H4,Calendrier!$A$2:$A$367,0)),0),"") -> 1 | K4: =IF(ISNUMBER(H4),I4*J4,"") -> 0 | L4: =IF(D4="","",IF(COUNTIF(Paramètres!$A$11:$A$40,D4)>0,1,0)) -> 1
B5: Mina Moussa | C5: janv 02 2026 12:51PM | D5: =IF(B5="","",TRIM(B5)) -> Mina Moussa | E5: =IF($C5="","",LEFT($C5,FIND(" ",$C5)-1)) -> janv | F5: =IF($C5="","",IFERROR(VALUE(LEFT(MID($C5,FIND(" ",$C5)+1,20),FIND(" ",MID($C5,FIND(" ",$C5)+1,20))-1)),"?")) -> 2 | G5: =IF($C5="","",IFERROR(VALUE(MID(MID($C5,FIND(" ",$C5)+1,20),FIND(" ",MID($C5,FIND(" ",$C5)+1,20))+1,4)),"?")) -> 2026 | H5: =IF($C5="","",IFERROR(DATE(G5,VLOOKUP(E5,Paramètres!$K$11:$L$40,2,FALSE()),F5),"?")) -> 46024 | I5: =IF(ISNUMBER(H5),IF(COUNTIFS($D$2:D5,D5,$H$2:H5,H5)=1,1,0),"") -> 0 | J5: =IF(ISNUMBER(H5),IFERROR(INDEX(Calendrier!$C$2:$C$367,MATCH(H5,Calendrier!$A$2:$A$367,0)),0),"") -> 1 | K5: =IF(ISNUMBER(H5),I5*J5,"") -> 0 | L5: =IF(D5="","",IF(COUNTIF(Paramètres!$A$11:$A$40,D5)>0,1,0)) -> 1
B6: Mina Moussa | C6: janv 02 2026 5:55PM | D6: =IF(B6="","",TRIM(B6)) -> Mina Moussa | E6: =IF($C6="","",LEFT($C6,FIND(" ",$C6)-1)) -> janv | F6: =IF($C6="","",IFERROR(VALUE(LEFT(MID($C6,FIND(" ",$C6)+1,20),FIND(" ",MID($C6,FIND(" ",$C6)+1,20))-1)),"?")) -> 2 | G6: =IF($C6="","",IFERROR(VALUE(MID(MID($C6,FIND(" ",$C6)+1,20),FIND(" ",MID($C6,FIND(" ",$C6)+1,20))+1,4)),"?")) -> 2026 | H6: =IF($C6="","",IFERROR(DATE(G6,VLOOKUP(E6,Paramètres!$K$11:$L$40,2,FALSE()),F6),"?")) -> 46024 | I6: =IF(ISNUMBER(H6),IF(COUNTIFS($D$2:D6,D6,$H$2:H6,H6)=1,1,0),"") -> 0 | J6: =IF(ISNUMBER(H6),IFERROR(INDEX(Calendrier!$C$2:$C$367,MATCH(H6,Calendrier!$A$2:$A$367,0)),0),"") -> 1 | K6: =IF(ISNUMBER(H6),I6*J6,"") -> 0 | L6: =IF(D6="","",IF(COUNTIF(Paramètres!$A$11:$A$40,D6)>0,1,0)) -> 1
B7: Mina Moussa | C7: janv 05 2026 4:26PM | D7: =IF(B7="","",TRIM(B7)) -> Mina Moussa | E7: =IF($C7="","",LEFT($C7,FIND(" ",$C7)-1)) -> janv | F7: =IF($C7="","",IFERROR(VALUE(LEFT(MID($C7,FIND(" ",$C7)+1,20),FIND(" ",MID($C7,FIND(" ",$C7)+1,20))-1)),"?")) -> 5 | G7: =IF($C7="","",IFERROR(VALUE(MID(MID($C7,FIND(" ",$C7)+1,20),FIND(" ",MID($C7,FIND(" ",$C7)+1,20))+1,4)),"?")) -> 2026 | H7: =IF($C7="","",IFERROR(DATE(G7,VLOOKUP(E7,Paramètres!$K$11:$L$40,2,FALSE()),F7),"?")) -> 46027 | I7: =IF(ISNUMBER(H7),IF(COUNTIFS($D$2:D7,D7,$H$2:H7,H7)=1,1,0),"") -> 1 | J7: =IF(ISNUMBER(H7),IFERROR(INDEX(Calendrier!$C$2:$C$367,MATCH(H7,Calendrier!$A$2:$A$367,0)),0),"") -> 1 | K7: =IF(ISNUMBER(H7),I7*J7,"") -> 1 | L7: =IF(D7="","",IF(COUNTIF(Paramètres!$A$11:$A$40,D7)>0,1,0)) -> 1
B8: Mina Moussa | C8: janv 06 2026 9:58AM | D8: =IF(B8="","",TRIM(B8)) -> Mina Moussa | E8: =IF($C8="","",LEFT($C8,FIND(" ",$C8)-1)) -> janv | F8: =IF($C8="","",IFERROR(VALUE(LEFT(MID($C8,FIND(" ",$C8)+1,20),FIND(" ",MID($C8,FIND(" ",$C8)+1,20))-1)),"?")) -> 6 | G8: =IF($C8="","",IFERROR(VALUE(MID(MID($C8,FIND(" ",$C8)+1,20),FIND(" ",MID($C8,FIND(" ",$C8)+1,20))+1,4)),"?")) -> 2026 | H8: =IF($C8="","",IFERROR(DATE(G8,VLOOKUP(E8,Paramètres!$K$11:$L$40,2,FALSE()),F8),"?")) -> 46028 | I8: =IF(ISNUMBER(H8),IF(COUNTIFS($D$2:D8,D8,$H$2:H8,H8)=1,1,0),"") -> 1 | J8: =IF(ISNUMBER(H8),IFERROR(INDEX(Calendrier!$C$2:$C$367,MATCH(H8,Calendrier!$A$2:$A$367,0)),0),"") -> 1 | K8: =IF(ISNUMBER(H8),I8*J8,"") -> 1 | L8: =IF(D8="","",IF(COUNTIF(Paramètres!$A$11:$A$40,D8)>0,1,0)) -> 1
B9: Mina Moussa | C9: janv 07 2026 9:49AM | D9: =IF(B9="","",TRIM(B9)) -> Mina Moussa | E9: =IF($C9="","",LEFT($C9,FIND(" ",$C9)-1)) -> janv | F9: =IF($C9="","",IFERROR(VALUE(LEFT(MID($C9,FIND(" ",$C9)+1,20),FIND(" ",MID($C9,FIND(" ",$C9)+1,20))-1)),"?")) -> 7 | G9: =IF($C9="","",IFERROR(VALUE(MID(MID($C9,FIND(" ",$C9)+1,20),FIND(" ",MID($C9,FIND(" ",$C9)+1,20))+1,4)),"?")) -> 2026 | H9: =IF($C9="","",IFERROR(DATE(G9,VLOOKUP(E9,Paramètres!$K$11:$L$40,2,FALSE()),F9),"?")) -> 46029 | I9: =IF(ISNUMBER(H9),IF(COUNTIFS($D$2:D9,D9,$H$2:H9,H9)=1,1,0),"") -> 1 | J9: =IF(ISNUMBER(H9),IFERROR(INDEX(Calendrier!$C$2:$C$367,MATCH(H9,Calendrier!$A$2:$A$367,0)),0),"") -> 1 | K9: =IF(ISNUMBER(H9),I9*J9,"") -> 1 | L9: =IF(D9="","",IF(COUNTIF(Paramètres!$A$11:$A$40,D9)>0,1,0)) -> 1
B10: Mina Moussa | C10: janv 07 2026 10:01AM | D10: =IF(B10="","",TRIM(B10)) -> Mina Moussa | E10: =IF($C10="","",LEFT($C10,FIND(" ",$C10)-1)) -> janv | F10: =IF($C10="","",IFERROR(VALUE(LEFT(MID($C10,FIND(" ",$C10)+1,20),FIND(" ",MID($C10,FIND(" ",$C10)+1,20))-1)),"?")) -> 7 | G10: =IF($C10="","",IFERROR(VALUE(MID(MID($C10,FIND(" ",$C10)+1,20),FIND(" ",MID($C10,FIND(" ",$C10)+1,20))+1,4)),"?")) -> 2026 | H10: =IF($C10="","",IFERROR(DATE(G10,VLOOKUP(E10,Paramètres!$K$11:$L$40,2,FALSE()),F10),"?")) -> 46029 | I10: =IF(ISNUMBER(H10),IF(COUNTIFS($D$2:D10,D10,$H$2:H10,H10)=1,1,0),"") -> 0 | J10: =IF(ISNUMBER(H10),IFERROR(INDEX(Calendrier!$C$2:$C$367,MATCH(H10,Calendrier!$A$2:$A$367,0)),0),"") -> 1 | K10: =IF(ISNUMBER(H10),I10*J10,"") -> 0 | L10: =IF(D10="","",IF(COUNTIF(Paramètres!$A$11:$A$40,D10)>0,1,0)) -> 1
B11: Mina Moussa | C11: janv 07 2026 1:34PM | D11: =IF(B11="","",TRIM(B11)) -> Mina Moussa | E11: =IF($C11="","",LEFT($C11,FIND(" ",$C11)-1)) -> janv | F11: =IF($C11="","",IFERROR(VALUE(LEFT(MID($C11,FIND(" ",$C11)+1,20),FIND(" ",MID($C11,FIND(" ",$C11)+1,20))-1)),"?")) -> 7 | G11: =IF($C11="","",IFERROR(VALUE(MID(MID($C11,FIND(" ",$C11)+1,20),FIND(" ",MID($C11,FIND(" ",$C11)+1,20))+1,4)),"?")) -> 2026 | H11: =IF($C11="","",IFERROR(DATE(G11,VLOOKUP(E11,Paramètres!$K$11:$L$40,2,FALSE()),F11),"?")) -> 46029 | I11: =IF(ISNUMBER(H11),IF(COUNTIFS($D$2:D11,D11,$H$2:H11,H11)=1,1,0),"") -> 0 | J11: =IF(ISNUMBER(H11),IFERROR(INDEX(Calendrier!$C$2:$C$367,MATCH(H11,Calendrier!$A$2:$A$367,0)),0),"") -> 1 | K11: =IF(ISNUMBER(H11),I11*J11,"") -> 0 | L11: =IF(D11="","",IF(COUNTIF(Paramètres!$A$11:$A$40,D11)>0,1,0)) -> 1
B12: Mina Moussa | C12: janv 07 2026 2:33PM | D12: =IF(B12="","",TRIM(B12)) -> Mina Moussa | E12: =IF($C12="","",LEFT($C12,FIND(" ",$C12)-1)) -> janv | F12: =IF($C12="","",IFERROR(VALUE(LEFT(MID($C12,FIND(" ",$C12)+1,20),FIND(" ",MID($C12,FIND(" ",$C12)+1,20))-1)),"?")) -> 7 | G12: =IF($C12="","",IFERROR(VALUE(MID(MID($C12,FIND(" ",$C12)+1,20),FIND(" ",MID($C12,FIND(" ",$C12)+1,20))+1,4)),"?")) -> 2026 | H12: =IF($C12="","",IFERROR(DATE(G12,VLOOKUP(E12,Paramètres!$K$11:$L$40,2,FALSE()),F12),"?")) -> 46029 | I12: =IF(ISNUMBER(H12),IF(COUNTIFS($D$2:D12,D12,$H$2:H12,H12)=1,1,0),"") -> 0 | J12: =IF(ISNUMBER(H12),IFERROR(INDEX(Calendrier!$C$2:$C$367,MATCH(H12,Calendrier!$A$2:$A$367,0)),0),"") -> 1 | K12: =IF(ISNUMBER(H12),I12*J12,"") -> 0 | L12: =IF(D12="","",IF(COUNTIF(Paramètres!$A$11:$A$40,D12)>0,1,0)) -> 1
B13: Mina Moussa | C13: janv 07 2026 3:49PM | D13: =IF(B13="","",TRIM(B13)) -> Mina Moussa | E13: =IF($C13="","",LEFT($C13,FIND(" ",$C13)-1)) -> janv | F13: =IF($C13="","",IFERROR(VALUE(LEFT(MID($C13,FIND(" ",$C13)+1,20),FIND(" ",MID($C13,FIND(" ",$C13)+1,20))-1)),"?")) -> 7 | G13: =IF($C13="","",IFERROR(VALUE(MID(MID($C13,FIND(" ",$C13)+1,20),FIND(" ",MID($C13,FIND(" ",$C13)+1,20))+1,4)),"?")) -> 2026 | H13: =IF($C13="","",IFERROR(DATE(G13,VLOOKUP(E13,Paramètres!$K$11:$L$40,2,FALSE()),F13),"?")) -> 46029 | I13: =IF(ISNUMBER(H13),IF(COUNTIFS($D$2:D13,D13,$H$2:H13,H13)=1,1,0),"") -> 0 | J13: =IF(ISNUMBER(H13),IFERROR(INDEX(Calendrier!$C$2:$C$367,MATCH(H13,Calendrier!$A$2:$A$367,0)),0),"") -> 1 | K13: =IF(ISNUMBER(H13),I13*J13,"") -> 0 | L13: =IF(D13="","",IF(COUNTIF(Paramètres!$A$11:$A$40,D13)>0,1,0)) -> 1
... B923: Imre Kapusi | C923: sept 23 2026 10:01AM | D923: =IF(B923="","",TRIM(B923)) -> Imre Kapusi | E923: =IF($C923="","",LEFT($C923,FIND(" ",$C923)-1)) -> sept | F923: =IF($C923="","",IFERROR(VALUE(LEFT(MID($C923,FIND(" ",$C923)+1,20),FIND(" ",MID($C923,FIND(" ",$C923)+1,20))-1)),"?")) -> 23 | G923: =IF($C923="","",IFERROR(VALUE(MID(MID($C923,FIND(" ",$C923)+1,20),FIND(" ",MID($C923,FIND(" ",$C923)+1,20))+1,4)),"?")) -> 2026 | H923: =IF($C923="","",IFERROR(DATE(G923,VLOOKUP(E923,Paramètres!$K$11:$L$40,2,FALSE()),F923),"?")) -> 46288 | I923: =IF(ISNUMBER(H923),IF(COUNTIFS($D$2:D923,D923,$H$2:H923,H923)=1,1,0),"") -> 1 | J923: =IF(ISNUMBER(H923),IFERROR(INDEX(Calendrier!$C$2:$C$367,MATCH(H923,Calendrier!$A$2:$A$367,0)),0),"") -> 1 | K923: =IF(ISNUMBER(H923),I923*J923,"") -> 1 | L923: =IF(D923="","",IF(COUNTIF(Paramètres!$A$11:$A$40,D923)>0,1,0)) -> 1
D924: =IF(B924="","",TRIM(B924)) | E924: =IF($C924="","",LEFT($C924,FIND(" ",$C924)-1)) | F924: =IF($C924="","",IFERROR(VALUE(LEFT(MID($C924,FIND(" ",$C924)+1,20),FIND(" ",MID($C924,FIND(" ",$C924)+1,20))-1)),"?")) | G924: =IF($C924="","",IFERROR(VALUE(MID(MID($C924,FIND(" ",$C924)+1,20),FIND(" ",MID($C924,FIND(" ",$C924)+1,20))+1,4)),"?")) | H924: =IF($C924="","",IFERROR(DATE(G924,VLOOKUP(E924,Paramètres!$K$11:$L$40,2,FALSE()),F924),"?")) | I924: =IF(ISNUMBER(H924),IF(COUNTIFS($D$2:D924,D924,$H$2:H924,H924)=1,1,0),"") | J924: =IF(ISNUMBER(H924),IFERROR(INDEX(Calendrier!$C$2:$C$367,MATCH(H924,Calendrier!$A$2:$A$367,0)),0),"") | K924: =IF(ISNUMBER(H924),I924*J924,"") | L924: =IF(D924="","",IF(COUNTIF(Paramètres!$A$11:$A$40,D924)>0,1,0))
D925: =IF(B925="","",TRIM(B925)) | E925: =IF($C925="","",LEFT($C925,FIND(" ",$C925)-1)) | F925: =IF($C925="","",IFERROR(VALUE(LEFT(MID($C925,FIND(" ",$C925)+1,20),FIND(" ",MID($C925,FIND(" ",$C925)+1,20))-1)),"?")) | G925: =IF($C925="","",IFERROR(VALUE(MID(MID($C925,FIND(" ",$C925)+1,20),FIND(" ",MID($C925,FIND(" ",$C925)+1,20))+1,4)),"?")) | H925: =IF($C925="","",IFERROR(DATE(G925,VLOOKUP(E925,Paramètres!$K$11:$L$40,2,FALSE()),F925),"?")) | I925: =IF(ISNUMBER(H925),IF(COUNTIFS($D$2:D925,D925,$H$2:H925,H925)=1,1,0),"") | J925: =IF(ISNUMBER(H925),IFERROR(INDEX(Calendrier!$C$2:$C$367,MATCH(H925,Calendrier!$A$2:$A$367,0)),0),"") | K925: =IF(ISNUMBER(H925),I925*J925,"") | L925: =IF(D925="","",IF(COUNTIF(Paramètres!$A$11:$A$40,D925)>0,1,0))
D926: =IF(B926="","",TRIM(B926)) | E926: =IF($C926="","",LEFT($C926,FIND(" ",$C926)-1)) | F926: =IF($C926="","",IFERROR(VALUE(LEFT(MID($C926,FIND(" ",$C926)+1,20),FIND(" ",MID($C926,FIND(" ",$C926)+1,20))-1)),"?")) | G926: =IF($C926="","",IFERROR(VALUE(MID(MID($C926,FIND(" ",$C926)+1,20),FIND(" ",MID($C926,FIND(" ",$C926)+1,20))+1,4)),"?")) | H926: =IF($C926="","",IFERROR(DATE(G926,VLOOKUP(E926,Paramètres!$K$11:$L$40,2,FALSE()),F926),"?")) | I926: =IF(ISNUMBER(H926),IF(COUNTIFS($D$2:D926,D926,$H$2:H926,H926)=1,1,0),"") | J926: =IF(ISNUMBER(H926),IFERROR(INDEX(Calendrier!$C$2:$C$367,MATCH(H926,Calendrier!$A$2:$A$367,0)),0),"") | K926: =IF(ISNUMBER(H926),I926*J926,"") | L926: =IF(D926="","",IF(COUNTIF(Paramètres!$A$11:$A$40,D926)>0,1,0))
D927: =IF(B927="","",TRIM(B927)) | E927: =IF($C927="","",LEFT($C927,FIND(" ",$C927)-1)) | F927: =IF($C927="","",IFERROR(VALUE(LEFT(MID($C927,FIND(" ",$C927)+1,20),FIND(" ",MID($C927,FIND(" ",$C927)+1,20))-1)),"?")) | G927: =IF($C927="","",IFERROR(VALUE(MID(MID($C927,FIND(" ",$C927)+1,20),FIND(" ",MID($C927,FIND(" ",$C927)+1,20))+1,4)),"?")) | H927: =IF($C927="","",IFERROR(DATE(G927,VLOOKUP(E927,Paramètres!$K$11:$L$40,2,FALSE()),F927),"?")) | I927: =IF(ISNUMBER(H927),IF(COUNTIFS($D$2:D927,D927,$H$2:H927,H927)=1,1,0),"") | J927: =IF(ISNUMBER(H927),IFERROR(INDEX(Calendrier!$C$2:$C$367,MATCH(H927,Calendrier!$A$2:$A$367,0)),0),"") | K927: =IF(ISNUMBER(H927),I927*J927,"") | L927: =IF(D927="","",IF(COUNTIF(Paramètres!$A$11:$A$40,D927)>0,1,0))
D928: =IF(B928="","",TRIM(B928)) | E928: =IF($C928="","",LEFT($C928,FIND(" ",$C928)-1)) | F928: =IF($C928="","",IFERROR(VALUE(LEFT(MID($C928,FIND(" ",$C928)+1,20),FIND(" ",MID($C928,FIND(" ",$C928)+1,20))-1)),"?")) | G928: =IF($C928="","",IFERROR(VALUE(MID(MID($C928,FIND(" ",$C928)+1,20),FIND(" ",MID($C928,FIND(" ",$C928)+1,20))+1,4)),"?")) | H928: =IF($C928="","",IFERROR(DATE(G928,VLOOKUP(E928,Paramètres!$K$11:$L$40,2,FALSE()),F928),"?")) | I928: =IF(ISNUMBER(H928),IF(COUNTIFS($D$2:D928,D928,$H$2:H928,H928)=1,1,0),"") | J928: =IF(ISNUMBER(H928),IFERROR(INDEX(Calendrier!$C$2:$C$367,MATCH(H928,Calendrier!$A$2:$A$367,0)),0),"") | K928: =IF(ISNUMBER(H928),I928*J928,"") | L928: =IF(D928="","",IF(COUNTIF(Paramètres!$A$11:$A$40,D928)>0,1,0))
D929: =IF(B929="","",TRIM(B929)) | E929: =IF($C929="","",LEFT($C929,FIND(" ",$C929)-1)) | F929: =IF($C929="","",IFERROR(VALUE(LEFT(MID($C929,FIND(" ",$C929)+1,20),FIND(" ",MID($C929,FIND(" ",$C929)+1,20))-1)),"?")) | G929: =IF($C929="","",IFERROR(VALUE(MID(MID($C929,FIND(" ",$C929)+1,20),FIND(" ",MID($C929,FIND(" ",$C929)+1,20))+1,4)),"?")) | H929: =IF($C929="","",IFERROR(DATE(G929,VLOOKUP(E929,Paramètres!$K$11:$L$40,2,FALSE()),F929),"?")) | I929: =IF(ISNUMBER(H929),IF(COUNTIFS($D$2:D929,D929,$H$2:H929,H929)=1,1,0),"") | J929: =IF(ISNUMBER(H929),IFERROR(INDEX(Calendrier!$C$2:$C$367,MATCH(H929,Calendrier!$A$2:$A$367,0)),0),"") | K929: =IF(ISNUMBER(H929),I929*J929,"") | L929: =IF(D929="","",IF(COUNTIF(Paramètres!$A$11:$A$40,D929)>0,1,0))
D930: =IF(B930="","",TRIM(B930)) | E930: =IF($C930="","",LEFT($C930,FIND(" ",$C930)-1)) | F930: =IF($C930="","",IFERROR(VALUE(LEFT(MID($C930,FIND(" ",$C930)+1,20),FIND(" ",MID($C930,FIND(" ",$C930)+1,20))-1)),"?")) | G930: =IF($C930="","",IFERROR(VALUE(MID(MID($C930,FIND(" ",$C930)+1,20),FIND(" ",MID($C930,FIND(" ",$C930)+1,20))+1,4)),"?")) | H930: =IF($C930="","",IFERROR(DATE(G930,VLOOKUP(E930,Paramètres!$K$11:$L$40,2,FALSE()),F930),"?")) | I930: =IF(ISNUMBER(H930),IF(COUNTIFS($D$2:D930,D930,$H$2:H930,H930)=1,1,0),"") | J930: =IF(ISNUMBER(H930),IFERROR(INDEX(Calendrier!$C$2:$C$367,MATCH(H930,Calendrier!$A$2:$A$367,0)),0),"") | K930: =IF(ISNUMBER(H930),I930*J930,"") | L930: =IF(D930="","",IF(COUNTIF(Paramètres!$A$11:$A$40,D930)>0,1,0))
D931: =IF(B931="","",TRIM(B931)) | E931: =IF($C931="","",LEFT($C931,FIND(" ",$C931)-1)) | F931: =IF($C931="","",IFERROR(VALUE(LEFT(MID($C931,FIND(" ",$C931)+1,20),FIND(" ",MID($C931,FIND(" ",$C931)+1,20))-1)),"?")) | G931: =IF($C931="","",IFERROR(VALUE(MID(MID($C931,FIND(" ",$C931)+1,20),FIND(" ",MID($C931,FIND(" ",$C931)+1,20))+1,4)),"?")) | H931: =IF($C931="","",IFERROR(DATE(G931,VLOOKUP(E931,Paramètres!$K$11:$L$40,2,FALSE()),F931),"?")) | I931: =IF(ISNUMBER(H931),IF(COUNTIFS($D$2:D931,D931,$H$2:H931,H931)=1,1,0),"") | J931: =IF(ISNUMBER(H931),IFERROR(INDEX(Calendrier!$C$2:$C$367,MATCH(H931,Calendrier!$A$2:$A$367,0)),0),"") | K931: =IF(ISNUMBER(H931),I931*J931,"") | L931: =IF(D931="","",IF(COUNTIF(Paramètres!$A$11:$A$40,D931)>0,1,0))
D932: =IF(B932="","",TRIM(B932)) | E932: =IF($C932="","",LEFT($C932,FIND(" ",$C932)-1)) | F932: =IF($C932="","",IFERROR(VALUE(LEFT(MID($C932,FIND(" ",$C932)+1,20),FIND(" ",MID($C932,FIND(" ",$C932)+1,20))-1)),"?")) | G932: =IF($C932="","",IFERROR(VALUE(MID(MID($C932,FIND(" ",$C932)+1,20),FIND(" ",MID($C932,FIND(" ",$C932)+1,20))+1,4)),"?")) | H932: =IF($C932="","",IFERROR(DATE(G932,VLOOKUP(E932,Paramètres!$K$11:$L$40,2,FALSE()),F932),"?")) | I932: =IF(ISNUMBER(H932),IF(COUNTIFS($D$2:D932,D932,$H$2:H932,H932)=1,1,0),"") | J932: =IF(ISNUMBER(H932),IFERROR(INDEX(Calendrier!$C$2:$C$367,MATCH(H932,Calendrier!$A$2:$A$367,0)),0),"") | K932: =IF(ISNUMBER(H932),I932*J932,"") | L932: =IF(D932="","",IF(COUNTIF(Paramètres!$A$11:$A$40,D932)>0,1,0))
D933: =IF(B933="","",TRIM(B933)) | E933: =IF($C933="","",LEFT($C933,FIND(" ",$C933)-1)) | F933: =IF($C933="","",IFERROR(VALUE(LEFT(MID($C933,FIND(" ",$C933)+1,20),FIND(" ",MID($C933,FIND(" ",$C933)+1,20))-1)),"?")) | G933: =IF($C933="","",IFERROR(VALUE(MID(MID($C933,FIND(" ",$C933)+1,20),FIND(" ",MID($C933,FIND(" ",$C933)+1,20))+1,4)),"?")) | H933: =IF($C933="","",IFERROR(DATE(G933,VLOOKUP(E933,Paramètres!$K$11:$L$40,2,FALSE()),F933),"?")) | I933: =IF(ISNUMBER(H933),IF(COUNTIFS($D$2:D933,D933,$H$2:H933,H933)=1,1,0),"") | J933: =IF(ISNUMBER(H933),IFERROR(INDEX(Calendrier!$C$2:$C$367,MATCH(H933,Calendrier!$A$2:$A$367,0)),0),"") | K933: =IF(ISNUMBER(H933),I933*J933,"") | L933: =IF(D933="","",IF(COUNTIF(Paramètres!$A$11:$A$40,D933)>0,1,0))
D934: =IF(B934="","",TRIM(B934)) | E934: =IF($C934="","",LEFT($C934,FIND(" ",$C934)-1)) | F934: =IF($C934="","",IFERROR(VALUE(LEFT(MID($C934,FIND(" ",$C934)+1,20),FIND(" ",MID($C934,FIND(" ",$C934)+1,20))-1)),"?")) | G934: =IF($C934="","",IFERROR(VALUE(MID(MID($C934,FIND(" ",$C934)+1,20),FIND(" ",MID($C934,FIND(" ",$C934)+1,20))+1,4)),"?")) | H934: =IF($C934="","",IFERROR(DATE(G934,VLOOKUP(E934,Paramètres!$K$11:$L$40,2,FALSE()),F934),"?")) | I934: =IF(ISNUMBER(H934),IF(COUNTIFS($D$2:D934,D934,$H$2:H934,H934)=1,1,0),"") | J934: =IF(ISNUMBER(H934),IFERROR(INDEX(Calendrier!$C$2:$C$367,MATCH(H934,Calendrier!$A$2:$A$367,0)),0),"") | K934: =IF(ISNUMBER(H934),I934*J934,"") | L934: =IF(D934="","",IF(COUNTIF(Paramètres!$A$11:$A$40,D934)>0,1,0))
D935: =IF(B935="","",TRIM(B935)) | E935: =IF($C935="","",LEFT($C935,FIND(" ",$C935)-1)) | F935: =IF($C935="","",IFERROR(VALUE(LEFT(MID($C935,FIND(" ",$C935)+1,20),FIND(" ",MID($C935,FIND(" ",$C935)+1,20))-1)),"?")) | G935: =IF($C935="","",IFERROR(VALUE(MID(MID($C935,FIND(" ",$C935)+1,20),FIND(" ",MID($C935,FIND(" ",$C935)+1,20))+1,4)),"?")) | H935: =IF($C935="","",IFERROR(DATE(G935,VLOOKUP(E935,Paramètres!$K$11:$L$40,2,FALSE()),F935),"?")) | I935: =IF(ISNUMBER(H935),IF(COUNTIFS($D$2:D935,D935,$H$2:H935,H935)=1,1,0),"") | J935: =IF(ISNUMBER(H935),IFERROR(INDEX(Calendrier!$C$2:$C$367,MATCH(H935,Calendrier!$A$2:$A$367,0)),0),"") | K935: =IF(ISNUMBER(H935),I935*J935,"") | L935: =IF(D935="","",IF(COUNTIF(Paramètres!$A$11:$A$40,D935)>0,1,0))
... D3001: =IF(B3001="","",TRIM(B3001)) | E3001: =IF($C3001="","",LEFT($C3001,FIND(" ",$C3001)-1)) | F3001: =IF($C3001="","",IFERROR(VALUE(LEFT(MID($C3001,FIND(" ",$C3001)+1,20),FIND(" ",MID($C3001,FIND(" ",$C3001)+1,20))-1)),"?")) | G3001: =IF($C3001="","",IFERROR(VALUE(MID(MID($C3001,FIND(" ",$C3001)+1,20),FIND(" ",MID($C3001,FIND(" ",$C3001)+1,20))+1,4)),"?")) | H3001: =IF($C3001="","",IFERROR(DATE(G3001,VLOOKUP(E3001,Paramètres!$K$11:$L$40,2,FALSE()),F3001),"?")) | I3001: =IF(ISNUMBER(H3001),IF(COUNTIFS($D$2:D3001,D3001,$H$2:H3001,H3001)=1,1,0),"") | J3001: =IF(ISNUMBER(H3001),IFERROR(INDEX(Calendrier!$C$2:$C$367,MATCH(H3001,Calendrier!$A$2:$A$367,0)),0),"") | K3001: =IF(ISNUMBER(H3001),I3001*J3001,"") | L3001: =IF(D3001="","",IF(COUNTIF(Paramètres!$A$11:$A$40,D3001)>0,1,0))

Sheet Calcul
A1: CALCUL (ne pas modifier) — jours attendus, jours consultés et taux par responsable et par mois
A2: Dernier jour présent dans le journal | C2: =MAX(Journal!$H$2:$H$3001) -> 46294 | E2: JOURS OUVRÉS ATTENDUS | P2: JOURS CONSULTÉS (≥1 accès, dédoublonnés, jours ouvrés) | AC2: TAUX D'UTILISATION (cible direction) | AP2: TAUX AJUSTÉ AU RÔLE (cible individuelle)
A3: Mois avec données (1/0) | C3: =IF(C$4<=$C$2,1,0) -> 1 | D3: =IF(D$4<=$C$2,1,0) -> 1 | E3: =IF(E$4<=$C$2,1,0) -> 1 | F3: =IF(F$4<=$C$2,1,0) -> 1 | G3: =IF(G$4<=$C$2,1,0) -> 1 | H3: =IF(H$4<=$C$2,1,0) -> 1 | I3: =IF(I$4<=$C$2,1,0) -> 1 | J3: =IF(J$4<=$C$2,1,0) -> 1 | ... N3: =IF(N$4<=$C$2,1,0) -> 0
A4: Responsable | C4: =DATE(Paramètres!$B$8,1,1) -> 46023 | D4: =DATE(Paramètres!$B$8,2,1) -> 46054 | E4: =DATE(Paramètres!$B$8,3,1) -> 46082 | F4: =DATE(Paramètres!$B$8,4,1) -> 46113 | G4: =DATE(Paramètres!$B$8,5,1) -> 46143 | H4: =DATE(Paramètres!$B$8,6,1) -> 46174 | I4: =DATE(Paramètres!$B$8,7,1) -> 46204 | J4: =DATE(Paramètres!$B$8,8,1) -> 46235 | K4: =DATE(Paramètres!$B$8,9,1) -> 46266 | L4: =DATE(Paramètres!$B$8,10,1) -> 46296 | M4: =DATE(Paramètres!$B$8,11,1) -> 46327 | N4: =DATE(Paramètres!$B$8,12,1) -> 46357 | P4: =C$4 -> 46023 | Q4: =D$4 -> 46054 | R4: =E$4 -> 46082 | S4: =F$4 -> 46113 | T4: =G$4 -> 46143 | U4: =H$4 -> 46174 | V4: =I$4 -> 46204 | W4: =J$4 -> 46235 | ... AA4: =N$4 -> 46357 | AC4: =C$4 -> 46023 | AD4: =D$4 -> 46054 | AE4: =E$4 -> 46082 | AF4: =F$4 -> 46113 | AG4: =G$4 -> 46143 | AH4: =H$4 -> 46174 | AI4: =I$4 -> 46204 | AJ4: =J$4 -> 46235 | ... AN4: =N$4 -> 46357 | AP4: =C$4 -> 46023 | AQ4: =D$4 -> 46054 | AR4: =E$4 -> 46082 | AS4: =F$4 -> 46113 | AT4: =G$4 -> 46143 | AU4: =H$4 -> 46174 | AV4: =I$4 -> 46204 | AW4: =J$4 -> 46235 | ... BA4: =N$4 -> 46357 | BC4: Actif (mois sél.) | BD4: Taux (mois sél.) | BE4: Clé de tri | BF4: Rang
